Workbook

Sheet IN
F2: ENTRADA DE MATERIALES CT | X2: REALIZADO POR: ANGEL SUNIAGA
B5: # | C5: O/C | D5: TRANSF. | E5: PROPIEDAD DE | F5: ORIGEN | G5: SEMANA | H5: FECHA | I5: MES | J5: NRO. SIM | K5: CODIGO TEPECA | L5: DESCRIPCION | M5: MARCA | N5: MODELO | O5: SERIAL | P5: UBICACIÓN | Q5: CANT | R5: UM | S5: CONDICION | T5: RECIBIDO POR: | U5: GERENCIA | V5: DPTO.SOLICITANTE | W5: USO | X5: UNIDAD | Y5: DESTINO
B6: 1 | C6: N/A | D6: NOTA DE ENTREGA #0017 | E6: TEPECA | F6: CPVEN | G6: 4 | H6: 29/08/2022 | I6: AGOSTO | J6: 43166 | K6: N/A | L6: HERRAMIENTA SAND VAC | P6: ALM PPAL | Q6: 2 | R6: JGO | S6: NUEVO | T6: ANGEL S | U6: ADMINISTRACION | V6: COILED TUBING | W6: RECEPCION DE HERRAMIENTA Y COMPONENTES ASOCIADOS A EQUIPO COILED TUBING PROVENIENTE DE PROVEEDOR EXTERNO CPVEN | X6: COILED TUBING | Y6: SAN ANTONIO INTERNATIONAL BASE-SAN JOSE DE GUANIPA
B7: 2 | C7: N/A | D7: NOTA DE ENTREGA #0018 | E7: TEPECA | F7: CPVEN | G7: 4 | H7: 29/08/2022 | I7: AGOSTO | J7: 43170 | K7: N/A | L7: DESIOMETERS MECANICOS | P7: ALM PPAL | Q7: 2 | R7: JGO | S7: NUEVO | T7: ANGEL S | U7: ADMINISTRACION | V7: COILED TUBING | W7: RECEPCION DE HERRAMIENTA Y COMPONENTES ASOCIADOS A EQUIPO COILED TUBING PROVENIENTE DE PROVEEDOR EXTERNO CPVEN | X7: COILED TUBING | Y7: SAN ANTONIO INTERNATIONAL BASE-SAN JOSE DE GUANIPA
B8: 3 | C8: N/A | D8: NOTA DE ENTREGA #0018 | E8: TEPECA | F8: CPVEN | G8: 4 | H8: 29/08/2022 | I8: AGOSTO | J8: 43170 | K8: N/A | L8: LLAVE DE FRICCION 2,5 | P8: ALM PPAL | Q8: 2 | R8: PZA | S8: NUEVO | T8: ANGEL S | U8: ADMINISTRACION | V8: COILED TUBING | W8: RECEPCION DE HERRAMIENTA Y COMPONENTES ASOCIADOS A EQUIPO COILED TUBING PROVENIENTE DE PROVEEDOR EXTERNO CPVEN | X8: COILED TUBING | Y8: SAN ANTONIO INTERNATIONAL BASE-SAN JOSE DE GUANIPA
B9: 4 | C9: N/A | D9: DEV-2022-00135 | E9: TEPECA | F9: PETROALIANZA | G9: 4 | H9: 29/08/2022 | I9: AGOSTO | J9: N/P | K9: N/A | L9: FLANGE 4-1/16" CIEGO | P9: GALPON 2 | Q9: 1 | R9: UND | S9: NUEVO | T9: RAFAEL B | U9: ADMINISTRACION | V9: COILED TUBING | W9: RETORNO DE MATERIAL POR PARTE DE EMPRESA PETROALIANZA. DONDE PERMANECIA EN CALIDAD DE PRESTAMO PARA PRUEBA DE BOP | X9: COILED TUBING | Y9: SAN ANTONIO INTERNATIONAL BASE-SAN JOSE DE GUANIPA
B10: 5 | C10: N/A | D10: DEV-2022-00135 | E10: TEPECA | F10: PETROALIANZA | G10: 4 | H10: 29/08/2022 | I10: AGOSTO | J10: N/P | K10: N/A | L10: ESPARRAGOS DE 1" | P10: GALPON 2 | Q10: 8 | R10: UND | S10: NUEVO | T10: RAFAEL B | U10: ADMINISTRACION | V10: COILED TUBING | W10: RETORNO DE MATERIAL POR PARTE DE EMPRESA PETROALIANZA. DONDE PERMANECIA EN CALIDAD DE PRESTAMO PARA PRUEBA DE BOP | X10: COILED TUBING | Y10: SAN ANTONIO INTERNATIONAL BASE-SAN JOSE DE GUANIPA
B11: 6 | C11: N/A | D11: DEV-2022-00135 | E11: TEPECA | F11: PETROALIANZA | G11: 4 | H11: 29/08/2022 | I11: AGOSTO | J11: N/P | K11: N/A | L11: TUERCA PARA ESPARRAGO 1" | P11: GALPON 2 | Q11: 8 | R11: UND | S11: NUEVO | T11: RAFAEL B | U11: ADMINISTRACION | V11: COILED TUBING | W11: RETORNO DE MATERIAL POR PARTE DE EMPRESA PETROALIANZA. DONDE PERMANECIA EN CALIDAD DE PRESTAMO PARA PRUEBA DE BOP | X11: COILED TUBING | Y11: SAN ANTONIO INTERNATIONAL BASE-SAN JOSE DE GUANIPA
B12: 7 | C12: N/A | D12: NOTA DE ENTREGA #0020 | E12: TEPECA | F12: TORNO MOLINA | G12: 1 | H12: 01/09/2022 | I12: SEPT | J12: 82 | K12: N/A | L12: TAPA DEL FLUID END 3-1/2" INCLUYE: JGO DE O-RING Y SEPARADOR DE TEFLON | P12: ALMPPAL | Q12: 1 | R12: UND | S12: FABRICADO | T12: ANGEL S | U12: ADMINISTACION | V12: COILED TUBING | W12: RECEPCION DE MATERIALES EN ALMACEN Y POSTERIOR ENTREGA A PERSONAL DE COILED TUBING PARA REPARACION EN BOMBA DE LODO DEL EQUIPO | X12: COILED TUBING | Y12: SAN ANTONIO INTERNATIONAL BASE-SAN JOSE DE GUANIPA
B13: 8 | C13: N/A | D13: NOTA DE ENTREGA #0020 | E13: TEPECA | F13: TORNO MOLINA | G13: 1 | H13: 01/09/2022 | I13: SEPT | J13: 82 | K13: N/A | L13: TAPA DEL FLUID END 3" INCLUYE: JGO DE O-RING Y SEPARADOR DE TEFLON | P13: ALMPPAL | Q13: 1 | R13: UND | S13: FABRICADO | T13: ANGEL S | U13: ADMINISTACION | V13: COILED TUBING | W13: RECEPCION DE MATERIALES EN ALMACEN Y POSTERIOR ENTREGA A PERSONAL DE COILED TUBING PARA REPARACION EN BOMBA DE LODO DEL EQUIPO | X13: COILED TUBING | Y13: SAN ANTONIO INTERNATIONAL BASE-SAN JOSE DE GUANIPA
B14: 9 | C14: N/A | D14: AL--2022-03323 | E14: TEPECA | F14: TEPECA | G14: 3 | H14: 13/09/2022 | I14: SEPT | J14: MO-2022-473 | K14: N/A | L14: BOMBA DE AGUA DE CAMION COILED TUBING P/N: 23522721, P/N: 8922383 | O14: 4260 | P14: ALMPPAL | Q14: 1 | R14: UND | S14: REPARADO | T14: RAFAEL B | U14: ADMINISTACION | V14: COILED TUBING | W14: RECEPCION DE MATERIAL PARA ASIGNACION A EQUIPO COILED TUBING UBICADO EN BASE SAI | X14: COILED TUBING | Y14: SAN ANTONIO INTERNATIONAL BASE-SAN JOSE DE GUANIPA
B15: 10 | C15: N/A | D15: AL--2022-03409 | E15: TEPECA | F15: TEPECA | G15: 4 | H15: 21/09/2022 | I15: SEPT | J15: N/P | K15: 1.004.0014.0051 | L15: TENSOR P / CADENA (PERRO) 3/8"-1/2" TIPO RACHET INCLUYE CERTIFICADOS DE CALIDAD | P15: ALMPPAL | Q15: 6 | R15: UND | S15: NUEVO | T15: JOSEPTT M | U15: ADMINISTACION | V15: COILED TUBING | W15: RECEPCION DE MATERIALES ASIGNADOS A EQUIPO COILED TUBING UBICADO EN BASE SAI | X15: COILED TUBING | Y15: SAN ANTONIO INTERNATIONAL BASE-SAN JOSE DE GUANIPA
B16: 11 | C16: N/A | D16: AL--2022-03409 | E16: TEPECA | F16: TEPECA | G16: 4 | H16: 21/09/2022 | I16: SEPT | J16: N/P | K16: 1.004.0014.0052 | L16: FAJA NYLON DOBLE CAPA 3" X 6M DEBE INCLUIR CERTIFICADOS DE CALIDAD | O16: FP030206-06 | P16: ALMPPAL | Q16: 1 | R16: UND | S16: NUEVO | T16: JOSEPTT M | U16: ADMINISTACION | V16: COILED TUBING | W16: RECEPCION DE MATERIALES ASIGNADOS A EQUIPO COILED TUBING UBICADO EN BASE SAI | X16: COILED TUBING | Y16: SAN ANTONIO INTERNATIONAL BASE-SAN JOSE DE GUANIPA
B17: 12 | C17: N/A | D17: AL--2022-03409 | E17: TEPECA | F17: TEPECA | G17: 4 | H17: 21/09/2022 | I17: SEPT | J17: N/P | K17: 1.004.0014.0052 | L17: FAJA NYLON DOBLE CAPA 3" X 6M DEBE INCLUIR CERTIFICADOS DE CALIDAD | O17: FP030206-01 | P17: ALMPPAL | Q17: 1 | R17: UND | S17: NUEVO | T17: JOSEPTT M | U17: ADMINISTACION | V17: COILED TUBING | W17: RECEPCION DE MATERIALES ASIGNADOS A EQUIPO COILED TUBING UBICADO EN BASE SAI | X17: COILED TUBING | Y17: SAN ANTONIO INTERNATIONAL BASE-SAN JOSE DE GUANIPA
B18: 13 | C18: N/A | D18: AL--2022-03409 | E18: TEPECA | F18: TEPECA | G18: 4 | H18: 21/09/2022 | I18: SEPT | J18: N/P | K18: 1.004.0014.0054 | L18: FAJA NYLON CON RACHET 2" X 30FT INCLUYE CERTIFICADO DE CALIDAD | P18: ALMPPAL | Q18: 3 | R18: UND | S18: NUEVO | T18: JOSEPTT M | U18: ADMINISTACION | V18: COILED TUBING | W18: RECEPCION DE MATERIALES ASIGNADOS A EQUIPO COILED TUBING UBICADO EN BASE SAI | X18: COILED TUBING | Y18: SAN ANTONIO INTERNATIONAL BASE-SAN JOSE DE GUANIPA
B19: 14 | C19: N/A | D19: AL--2022-03409 | E19: TEPECA | F19: TEPECA | G19: 4 | H19: 21/09/2022 | I19: SEPT | J19: N/P | K19: 1.004.0014.0053 | L19: FAJA NYLON CON RACHET 2" X 8MTS DEBE INCLUIR CERTIFICADO DE CALIDAD | P19: ALMPPAL | Q19: 1 | R19: UND | S19: NUEVO | T19: JOSEPTT M | U19: ADMINISTACION | V19: COILED TUBING | W19: RECEPCION DE MATERIALES ASIGNADOS A EQUIPO COILED TUBING UBICADO EN BASE SAI | X19: COILED TUBING | Y19: SAN ANTONIO INTERNATIONAL BASE-SAN JOSE DE GUANIPA
B20: 15 | C20: N/A | D20: AL--2022-03409 | E20: TEPECA | F20: TEPECA | G20: 4 | H20: 21/09/2022 | I20: SEPT | J20: N/P | K20: 1.004.0014.0053 | L20: PULPO CABLE ACERO 4 RAMALES 1/2" X 2N 1,500KG (INCLUYE GUARDA CABOS Y ANILLOS) | P20: ALMPPAL | Q20: 1 | R20: UND | S20: NUEVO | T20: JOSEPTT M | U20: ADMINISTACION | V20: COILED TUBING | W20: RECEPCION DE MATERIALES ASIGNADOS A EQUIPO COILED TUBING UBICADO EN BASE SAI | X20: COILED TUBING | Y20: SAN ANTONIO INTERNATIONAL BASE-SAN JOSE DE GUANIPA
B21: 16 | C21: N/A | D21: AL--2022-03409 | E21: TEPECA | F21: TEPECA | G21: 4 | H21: 21/09/2022 | I21: SEPT | J21: N/P | K21: 1.004.0014.0055 | L21: GRILLETE DE ACERO 3/4" C/ PERNO ROSCADO Y CUPILLA DE SEGURIDAD | P21: ALMPPAL | Q21: 4 | R21: UND | S21: NUEVO | T21: JOSEPTT M | U21: ADMINISTACION | V21: COILED TUBING | W21: RECEPCION DE MATERIALES ASIGNADOS A EQUIPO COILED TUBING UBICADO EN BASE SAI | X21: COILED TUBING | Y21: SAN ANTONIO INTERNATIONAL BASE-SAN JOSE DE GUANIPA
B22: 17 | C22: N/A | D22: AL--2022-03409 | E22: TEPECA | F22: TEPECA | G22: 4 | H22: 21/09/2022 | I22: SEPT | J22: N/P | K22: 1.006.0003.0012 | L22: GRASA GADUS S2 V220 2 PARA ALTA PRESION MARCA: SHELL (400 GRAMOS | P22: ALMPPAL | Q22: 10 | R22: UND | S22: NUEVO | T22: JOSEPTT M | U22: ADMINISTACION | V22: COILED TUBING | W22: RECEPCION DE MATERIALES ASIGNADOS A EQUIPO COILED TUBING UBICADO EN BASE SAI | X22: COILED TUBING | Y22: SAN ANTONIO INTERNATIONAL BASE-SAN JOSE DE GUANIPA
B23: 18 | C23: N/A | D23: AL--2022-03409 | E23: TEPECA | F23: TEPECA | G23: 4 | H23: 21/09/2022 | I23: SEPT | J23: N/P | K23: 3.007.0001.0003 | L23: CAUTIN TIPO LAPZ 60W / 120 VAC (INCLUYE 5 PIEZAS ADICIONALES) | P23: ALMPPAL | Q23: 1 | R23: UND | S23: NUEVO | T23: JOSEPTT M | U23: ADMINISTACION | V23: COILED TUBING | W23: RECEPCION DE MATERIALES ASIGNADOS A EQUIPO COILED TUBING UBICADO EN BASE SAI | X23: COILED TUBING | Y23: SAN ANTONIO INTERNATIONAL BASE-SAN JOSE DE GUANIPA
B24: 19 | C24: N/A | D24: AL--2022-03410 | E24: TEPECA | F24: TEPECA | G24: 4 | H24: 21/09/2022 | I24: SEPT | J24: N/P | K24: N/A | L24: JUEGO DE LLAVES COMBINADAS MILIMETRICAS 14 PZAS ( 10MM, 11MM, 12MM, 13MM, 14MM, 17MM, 19MM, 21MM, 22MM, 23MM, 24MM, 26MM, 30MM, 32MM) | M24: STANLEY | P24: ALMPPAL | Q24: 1 | R24: JGO | S24: NUEVO | T24: JOSEPTT M | U24: ADMINISTACION | V24: COILED TUBING | W24: RECEPCION DE MATERIALES ASIGNADOS A EQUIPO COILED TUBING UBICADO EN BASE SAI | X24: COILED TUBING | Y24: SAN ANTONIO INTERNATIONAL BASE-SAN JOSE DE GUANIPA
B25: 20 | C25: N/A | D25: AL--2022-03410 | E25: TEPECA | F25: TEPECA | G25: 4 | H25: 21/09/2022 | I25: SEPT | J25: N/P | K25: N/A | L25: JUEGO DE LLAVES COMBINADAS EN PULGADAS MOD. 86-970 14PZAS (3/8", 7/16", 1/2", 9/16", 5/8", 11/16", 3/4", 13/16", 7/8", 15/16", 1", 1-1/16", 1-1/8", 1-1/4" | M25: STANLEY | P25: ALMPPAL | Q25: 1 | R25: JGO | S25: NUEVO | T25: JOSEPTT M | U25: ADMINISTACION | V25: COILED TUBING | W25: RECEPCION DE MATERIALES ASIGNADOS A EQUIPO COILED TUBING UBICADO EN BASE SAI | X25: COILED TUBING | Y25: SAN ANTONIO INTERNATIONAL BASE-SAN JOSE DE GUANIPA
B26: 21 | C26: N/A | D26: AL--2022-03410 | E26: TEPECA | F26: TEPECA | G26: 4 | H26: 21/09/2022 | I26: SEPT | J26: N/P | K26: N/A | L26: PALA CUADRADA CON CABO LARGO | P26: ALMPPAL | Q26: 2 | R26: UND | S26: NUEVO | T26: JOSEPTT M | U26: ADMINISTACION | V26: COILED TUBING | W26: RECEPCION DE MATERIALES ASIGNADOS A EQUIPO COILED TUBING UBICADO EN BASE SAI | X26: COILED TUBING | Y26: SAN ANTONIO INTERNATIONAL BASE-SAN JOSE DE GUANIPA
B27: 22 | C27: N/A | D27: AL--2022-03410 | E27: TEPECA | F27: TEPECA | G27: 4 | H27: 21/09/2022 | I27: SEPT | J27: N/P | K27: 3.013.0001.0027 | L27: ARCO DE SEGUETA | M27: STANLEY | P27: ALMPPAL | Q27: 1 | R27: UND | S27: NUEVO | T27: JOSEPTT M | U27: ADMINISTACION | V27: COILED TUBING | W27: RECEPCION DE MATERIALES ASIGNADOS A EQUIPO COILED TUBING UBICADO EN BASE SAI | X27: COILED TUBING | Y27: SAN ANTONIO INTERNATIONAL BASE-SAN JOSE DE GUANIPA
B28: 23 | C28: N/A | D28: AL--2022-03410 | E28: TEPECA | F28: TEPECA | G28: 4 | H28: 21/09/2022 | I28: SEPT | J28: N/P | K28: N/A | L28: CARRETILLA DE ALBAÑILERIA | P28: ALMPPAL | Q28: 1 | R28: UND | S28: NUEVO | T28: JOSEPTT M | U28: ADMINISTACION | V28: COILED TUBING | W28: RECEPCION DE MATERIALES ASIGNADOS A EQUIPO COILED TUBING UBICADO EN BASE SAI | X28: COILED TUBING | Y28: SAN ANTONIO INTERNATIONAL BASE-SAN JOSE DE GUANIPA
B29: 24 | C29: N/A | D29: AL--2022-03464 | E29: TEPECA | F29: TEPECA | G29: 4 | H29: 26/09/2022 | I29: SEPT | J29: N/P | K29: 3.008.0001.0003 | L29: CAJA DE HERRAMIENTAS METALICA GRANDE | M29: PROTO | P29: ALMPPAL | Q29: 1 | R29: UND | S29: NUEVO | T29: EDUARDO G | U29: ADMINISTACION | V29: COILED TUBING | W29: RECEPCION DE HERRAMIENTAS Y MATERIAL AIGNADO AL EQUIPO COILED TUBING UBICADO EN BASE SAI | X29: COILED TUBING | Y29: SAN ANTONIO INTERNATIONAL BASE-SAN JOSE DE GUANIPA
B30: 25 | C30: N/A | D30: AL--2022-03464 | E30: TEPECA | F30: TEPECA | G30: 4 | H30: 26/09/2022 | I30: SEPT | J30: N/P | K30: 3.004.0007.0003 | L30: LLAVE AJUSTABLE 8" | M30: STANLEY | P30: ALMPPAL | Q30: 2 | R30: UND | S30: NUEVO | T30: EDUARDO G | U30: ADMINISTACION | V30: COILED TUBING | W30: RECEPCION DE HERRAMIENTAS Y MATERIAL AIGNADO AL EQUIPO COILED TUBING UBICADO EN BASE SAI | X30: COILED TUBING | Y30: SAN ANTONIO INTERNATIONAL BASE-SAN JOSE DE GUANIPA
B31: 26 | C31: N/A | D31: AL--2022-03464 | E31: TEPECA | F31: TEPECA | G31: 4 | H31: 26/09/2022 | I31: SEPT | J31: N/P | K31: N/A | L31: LLAVE AJUSTABLE 12" | M31: STANLEY | P31: ALMPPAL | Q31: 2 | R31: UND | S31: NUEVO | T31: EDUARDO G | U31: ADMINISTACION | V31: COILED TUBING | W31: RECEPCION DE HERRAMIENTAS Y MATERIAL AIGNADO AL EQUIPO COILED TUBING UBICADO EN BASE SAI | X31: COILED TUBING | Y31: SAN ANTONIO INTERNATIONAL BASE-SAN JOSE DE GUANIPA
B32: 27 | C32: N/A | D32: AL--2022-03464 | E32: TEPECA | F32: TEPECA | G32: 4 | H32: 26/09/2022 | I32: SEPT | J32: N/P | K32: N/A | L32: ALICATE ELECTRICO 8" MOD STANLEY 84-056 PETRUL PEL8PX | M32: PRETUL | P32: ALMPPAL | Q32: 2 | R32: UND | S32: NUEVO | T32: EDUARDO G | U32: ADMINISTACION | V32: COILED TUBING | W32: RECEPCION DE HERRAMIENTAS Y MATERIAL AIGNADO AL EQUIPO COILED TUBING UBICADO EN BASE SAI | X32: COILED TUBING | Y32: SAN ANTONIO INTERNATIONAL BASE-SAN JOSE DE GUANIPA
B33: 28 | C33: N/A | D33: AL--2022-03464 | E33: TEPECA | F33: TEPECA | G33: 4 | H33: 26/09/2022 | I33: SEPT | J33: N/P | K33: 3.004.0006.0009 | L33: ALICATE DE PRESION 10" | M33: TRUPER | P33: ALMPPAL | Q33: 2 | R33: UND | S33: NUEVO | T33: EDUARDO G | U33: ADMINISTACION | V33: COILED TUBING | W33: RECEPCION DE HERRAMIENTAS Y MATERIAL AIGNADO AL EQUIPO COILED TUBING UBICADO EN BASE SAI | X33: COILED TUBING | Y33: SAN ANTONIO INTERNATIONAL BASE-SAN JOSE DE GUANIPA
B34: 29 | C34: N/A | D34: AL--2022-03464 | E34: TEPECA | F34: TEPECA | G34: 4 | H34: 26/09/2022 | I34: SEPT | J34: N/P | K34: N/A | L34: MARTILLO DE CARPINTERO | M34: BELLOTA | P34: ALMPPAL | Q34: 2 | R34: UND | S34: NUEVO | T34: EDUARDO G | U34: ADMINISTACION | V34: COILED TUBING | W34: RECEPCION DE HERRAMIENTAS Y MATERIAL AIGNADO AL EQUIPO COILED TUBING UBICADO EN BASE SAI | X34: COILED TUBING | Y34: SAN ANTONIO INTERNATIONAL BASE-SAN JOSE DE GUANIPA
B35: 30 | C35: N/A | D35: AL--2022-03464 | E35: TEPECA | F35: TEPECA | G35: 4 | H35: 26/09/2022 | I35: SEPT | J35: N/P | K35: 3.002.0003.0009 | L35: JGO DE DADOS HEXAGONAL 3/8" A 1-1/4" CON CUADRANTE 1/2" / MOD: J54126 | M35: PROTO | P35: ALMPPAL | Q35: 1 | R35: JGO | S35: NUEVO | T35: EDUARDO G | U35: ADMINISTACION | V35: COILED TUBING | W35: RECEPCION DE HERRAMIENTAS Y MATERIAL AIGNADO AL EQUIPO COILED TUBING UBICADO EN BASE SAI | X35: COILED TUBING | Y35: SAN ANTONIO INTERNATIONAL BASE-SAN JOSE DE GUANIPA
B36: 31 | C36: N/A | D36: AL--2022-03464 | E36: TEPECA | F36: TEPECA | G36: 4 | H36: 26/09/2022 | I36: SEPT | J36: N/P | K36: 3.004.0006.0011 | L36: ALICATE PUNTA LARGA 8" | M36: TRUPER | P36: ALMPPAL | Q36: 2 | R36: UND | S36: NUEVO | T36: EDUARDO G | U36: ADMINISTACION | V36: COILED TUBING | W36: RECEPCION DE HERRAMIENTAS Y MATERIAL AIGNADO AL EQUIPO COILED TUBING UBICADO EN BASE SAI | X36: COILED TUBING | Y36: SAN ANTONIO INTERNATIONAL BASE-SAN JOSE DE GUANIPA
B37: 32 | C37: N/A | D37: AL--2022-03464 | E37: TEPECA | F37: TEPECA | G37: 4 | H37: 26/09/2022 | I37: SEPT | J37: N/P | K37: 3.004.0006.0026 | L37: ALICATE PELACABLE 9" MOD: 84-223 | M37: STANLEY | P37: ALMPPAL | Q37: 2 | R37: UND | S37: NUEVO | T37: EDUARDO G | U37: ADMINISTACION | V37: COILED TUBING | W37: RECEPCION DE HERRAMIENTAS Y MATERIAL AIGNADO AL EQUIPO COILED TUBING UBICADO EN BASE SAI | X37: COILED TUBING | Y37: SAN ANTONIO INTERNATIONAL BASE-SAN JOSE DE GUANIPA
B38: 33 | C38: N/A | D38: AL--2022-03464 | E38: TEPECA | F38: TEPECA | G38: 4 | H38: 26/09/2022 | I38: SEPT | J38: N/P | K38: 3.005.0001.0016 | L38: MANDARRIA DE HIERRO 6 LBS | M38: HERROAGRO | P38: ALMPPAL | Q38: 2 | R38: UND | S38: NUEVO | T38: EDUARDO G | U38: ADMINISTACION | V38: COILED TUBING | W38: RECEPCION DE HERRAMIENTAS Y MATERIAL AIGNADO AL EQUIPO COILED TUBING UBICADO EN BASE SAI | X38: COILED TUBING | Y38: SAN ANTONIO INTERNATIONAL BASE-SAN JOSE DE GUANIPA
B39: 34 | C39: N/A | D39: AL--2022-03465 | E39: TEPECA | F39: TEPECA | G39: 4 | H39: 26/09/2022 | I39: SEPT | J39: N/P | K39: 3.005.0001.0007 | L39: MANDARRIA DE BRONCE 3 KG | P39: ALMPPAL | Q39: 1 | R39: UND | S39: NUEVO | T39: EDUARDO G | U39: ADMINISTACION | V39: COILED TUBING | W39: RECEPCION DE HERRAMIENTAS Y MATERIAL AIGNADO AL EQUIPO COILED TUBING UBICADO EN BASE SAI | X39: COILED TUBING | Y39: SAN ANTONIO INTERNATIONAL BASE-SAN JOSE DE GUANIPA
B40: 35 | C40: N/A | D40: AL--2022-03465 | E40: TEPECA | F40: TEPECA | G40: 4 | H40: 26/09/2022 | I40: SEPT | J40: N/P | K40: 3.004.0005.0021 | L40: JGO DE DESTORNILLADORES MARCA STANLEY 10 PZAS PALA Y ESTRIA CON PUNTA MAGNETICA | M40: STANLEY | P40: ALMPPAL | Q40: 1 | R40: UND | S40: NUEVO | T40: EDUARDO G | U40: ADMINISTACION | V40: COILED TUBING | W40: RECEPCION DE HERRAMIENTAS Y MATERIAL AIGNADO AL EQUIPO COILED TUBING UBICADO EN BASE SAI | X40: COILED TUBING | Y40: SAN ANTONIO INTERNATIONAL BASE-SAN JOSE DE GUANIPA
B41: 36 | C41: N/A | D41: AL--2022-03465 | E41: TEPECA | F41: TEPECA | G41: 4 | H41: 26/09/2022 | I41: SEPT | J41: N/P | K41: N/A | L41: CEPILLO DE ALAMBRE | M41: SUPERIOP TOOLS | P41: ALMPPAL | Q41: 4 | R41: UND | S41: NUEVO | T41: EDUARDO G | U41: ADMINISTACION | V41: COILED TUBING | W41: RECEPCION DE HERRAMIENTAS Y MATERIAL AIGNADO AL EQUIPO COILED TUBING UBICADO EN BASE SAI | X41: COILED TUBING | Y41: SAN ANTONIO INTERNATIONAL BASE-SAN JOSE DE GUANIPA
B42: 37 | C42: N/A | D42: AL--2022-03465 | E42: TEPECA | F42: TEPECA | G42: 4 | H42: 26/09/2022 | I42: SEPT | J42: N/P | K42: N/A | L42: CORREA 17485 P / COILED TUBING | P42: ALMPPAL | Q42: 12 | R42: UND | S42: NUEVO | T42: EDUARDO G | U42: ADMINISTACION | V42: COILED TUBING | W42: RECEPCION DE HERRAMIENTAS Y MATERIAL AIGNADO AL EQUIPO COILED TUBING UBICADO EN BASE SAI | X42: COILED TUBING | Y42: SAN ANTONIO INTERNATIONAL BASE-SAN JOSE DE GUANIPA
B43: 38 | C43: N/A | D43: AL--2022-03465 | E43: TEPECA | F43: TEPECA | G43: 4 | H43: 26/09/2022 | I43: SEPT | J43: N/P | K43: 3.009.0003.0006 | L43: LIMA MEDIA LUNA 10" | P43: ALMPPAL | Q43: 2 | R43: UND | S43: NUEVO | T43: EDUARDO G | U43: ADMINISTACION | V43: COILED TUBING | W43: RECEPCION DE HERRAMIENTAS Y MATERIAL AIGNADO AL EQUIPO COILED TUBING UBICADO EN BASE SAI | X43: COILED TUBING | Y43: SAN ANTONIO INTERNATIONAL BASE-SAN JOSE DE GUANIPA
...

Sheet OUT
D2: MANTENIMIENTOS EJECUTADOS CT | X2: REALIZADO POR: ANGEL SUNIAGA
D5: INICIO | F5: FINAL | H5: CT | K5: MTTO | P5: MATERIALES | X5: OBSERVACIONES
B6: # | C6: NRO. REPORT | D6: FECHA | E6: HORA | F6: FECHA | G6: HORA | H6: UNIDAD | I6: EQUIPO | J6: HORAS T | K6: TIPO DE MTTO | L6: CAUSA O FALLA | M6: DESCRIPCION DE ACTIVIDAD | N6: ODS | O6: TIEMPO DE PARADA | P6: NRO. TRANS. ALM | Q6: DESCRIPCION DE INSUMOS | R6: P/N | S6: MARCA | T6: S/N | U6: CANT | V6: UND | W6: CONDICION | X6: USO
D7: 44796 | H7: TP-DCT-001 | I7: POWER PACK | K7: RUTINARIO | L7: HIGIENE Y SEGURIDAD | M7: LIMPIEZA DE CONEXIONES HIDRAULICAS | N7: N/A | O7: 0 | Q7: TRAPO PARA MANTENIMIENTO INDUSTRIAL | R7: N/A | U7: 4 | V7: KG | W7: NUEVO | X7: CONSUMIBLE REQUERIDO PARA REALIZACION DE LIMPIEZA EN CONEXIONES HIDRAULICAS DEL EQUIPO
D8: 44798 | H8: TP-DCT-001 | I8: UNIDAD DE BOMBEO | K8: PREVENTIVO | L8: PREVENCION ANTE FUTURAS FALLAS | M8: REEMPLAZO DE EMPAQUES EN BOMBA TRIPLEX "A" | N8: N/A | O8: 0 | Q8: PACKING DE BOMBA TRIPLEX DE 3-1/2", P/N: 6M-3500-WSPI-R | R8: 6M-3500-WSP1-R | U8: 1 | V8: KIT | W8: NUEVO | X8: ENTREGA DE MATERIAL REQUERIDO PARA USO EN BOMBA TRIPLEX DE UNIDAD DE BOMBEO DE EQUIPO
D9: 44798 | H9: TP-DCT-001 | I9: CT | K9: N/A | L9: PRESTAMO PARA PRUEBAS | M9: PRESTAMO CON CARÁCTER DEVOLUTIVO | N9: N/A | O9: 0 | Q9: FLANGE 4-1/16" CIEGO | R9: N/A | T9: 153-48330 | U9: 1 | V9: UND | W9: NUEVO | X9: SALIDA DE MATERIAL EN CALIDAD DE PRESTAMO PARA PRUEBA DE BOP. DEBE RETORNAR A BASE AL FINALIZAR PRUEBA
D10: 44798 | H10: TP-DCT-001 | I10: CT | K10: N/A | L10: PRESTAMO PARA PRUEBAS | M10: PRESTAMO CON CARÁCTER DEVOLUTIVO | N10: N/A | O10: 0 | Q10: ESPARRAGOS DE 1" | R10: N/A | U10: 8 | V10: UND | W10: NUEVO | X10: SALIDA DE MATERIAL EN CALIDAD DE PRESTAMO PARA PRUEBA DE BOP. DEBE RETORNAR A BASE AL FINALIZAR PRUEBA
D11: 44798 | H11: TP-DCT-001 | I11: CT | K11: N/A | L11: PRESTAMO PARA PRUEBAS | M11: PRESTAMO CON CARÁCTER DEVOLUTIVO | N11: N/A | O11: 0 | Q11: TUERCA PARA ESPARRAGO 1" | R11: N/A | U11: 8 | V11: UND | W11: NUEVO | X11: SALIDA DE MATERIAL EN CALIDAD DE PRESTAMO PARA PRUEBA DE BOP. DEBE RETORNAR A BASE AL FINALIZAR PRUEBA
D12: 44798 | H12: TP-DCT-001 | I12: UNIDAD DE BOMBEO | K12: PREVENTIVO | L12: PREVENCION ANTE FUTURAS FALLAS | M12: REEMPLAZO DE EMPAQUES EN BOMBA TRIPLEX "A" | N12: N/A | O12: 0 | Q12: O-RING 4" P/N: OR-343 | R12: OR-343 | U12: 3 | V12: UND | W12: NUEVO | X12: ENTREGA DE MATERIAL REQUERIDO PARA INSTALACION EN EQUIPO BOMBA
D13: 44798 | H13: TP-DCT-001 | I13: UNIDAD DE BOMBEO | K13: PREVENTIVO | L13: PREVENCION ANTE FUTURAS FALLAS | M13: REEMPLAZO DE EMPAQUES EN BOMBA TRIPLEX "A" | N13: N/A | O13: 0 | Q13: O-RING | R13: 65021190 | U13: 3 | V13: UND | W13: NUEVO | X13: ENTREGA DE MATERIAL REQUERIDO PARA INSTALACION EN EQUIPO BOMBA
D14: 44799 | H14: TP-DCT-001 | I14: UNIDAD DE BOMBEO | K14: CORRECTIVO | L14: FRACTURA EN TAPAS DE FLUID-END "A" | M14: ENVIO DE COMPONENTE PARA TOMA DE MEDIDAS EN TALLER EXTERNO "A. MOLINA" | N14: N/A | O14: 0 | Q14: TAPA DEL FLUID END 3-1/2" INCLUYE: JGO DE O-RING Y SEPARADOR DE TEFLON | R14: N/A | U14: 1 | V14: UND | W14: USADO | X14: ENVIO DE COMPONENTES DE LA BOMBA TRIPLEX ASOCIADO A EQUIPO COILED TUBING A PROVEEDOR EXTERNO (TOMA DE MEDIDAS PARA REALIZAR PRESUPUESTO)
D15: 44799 | H15: TP-DCT-001 | I15: UNIDAD DE BOMBEO | K15: CORRECTIVO | L15: FRACTURA EN TAPAS DE FLUID-END "B" | M15: ENVIO DE COMPONENTE PARA TOMA DE MEDIDAS EN TALLER EXTERNO "A. MOLINA" | N15: N/A | O15: 0 | Q15: TAPA DEL FLUID END 3" INCLUYE: JGO DE O-RING Y SEPARADOR DE TEFLON | R15: N/A | U15: 1 | V15: UND | W15: USADO | X15: ENVIO DE COMPONENTES DE LA BOMBA TRIPLEX ASOCIADO A EQUIPO COILED TUBING A PROVEEDOR EXTERNO (TOMA DE MEDIDAS PARA REALIZAR PRESUPUESTO)
D16: 44799 | H16: TP-DCT-001 | I16: POWER PACK | K16: PREVENTIVO | L16: PREVENCION ANTE FUTURAS FALLAS | M16: REEMPLAZO DE FILTRO DE AIRE DEL MOTOR S60 | N16: N/A | O16: 0 | Q16: FILTRO DE AIRE P/N: CAT-61-2505 | R16: CAT-612505 | S16: CAT | U16: 1 | V16: UND | W16: NUEVO | X16: ENTREGA DE MATERIAL REQUERIDO PARA ADAPTACION EN POWER PACK DE EQUIPO
D17: 44803 | H17: TP-DCT-001 | I17: UNIDAD DE BOMBEO | K17: CORRECTIVO | L17: FUGA DE REFRIGERANTE, EN SELLO DE LA BOMBA DE REFRIGERANTE | M17: ENVIO DE BOMBA A TALLER EXTERNO "MULTIBOMBAS EL TIGRE C.A" PARA REEMPLAZO DE SELLOS | N17: GP-CT-2022-004 | O17: 0 | Q17: BOMBA DE AGUA | R17: N/A | S17: DETROIT | T17: 4280 | U17: 1 | V17: UND | W17: USADO | X17: ENVIO DE COMPONENTE A SERVICIO DE REPARACION EN TALLER EXTERNO SEGÚN ODS: GP-CL-2022-004
D18: 44805 | H18: TP-DCT-001 | I18: UNIDAD DE BOMBEO | K18: CORRECTIVO | L18: FRACTURA EN TAPAS DE FLUID-END "A" | M18: INSTALACION DE TAPA DEL FLUID END "A" | N18: N/A | O18: 0 | Q18: TAPA DEL FLUID END 3-1/2" INCLUYE: JGO DE O-RING Y SEPARADOR DE TEFLON | R18: N/A | U18: 1 | V18: UND | W18: FABRICADO | X18: ENTREGA DE MATERIALES PARA REPARACION EN BOMBA DE LODO DEL EQUIPO
D19: 44805 | H19: TP-DCT-001 | I19: UNIDAD DE BOMBEO | K19: CORRECTIVO | L19: FRACTURA EN TAPAS DE FLUID-END "B" | M19: INSTALACION DE TAPA DEL FLUID END "B" | N19: N/A | O19: 0 | Q19: TAPA DEL FLUID END 3" INCLUYE: JGO DE O-RING Y SEPARADOR DE TEFLON | R19: N/A | U19: 1 | V19: UND | W19: FABRICADO | X19: ENTREGA DE MATERIALES PARA REPARACION EN BOMBA DE LODO DEL EQUIPO
D20: 44809 | H20: TP-DCT-001 | I20: UNIDAD DE BOMBEO | K20: CORRECTIVO | L20: FRACTURA EN TAPAS DE FLUID-END "A" | M20: INSTALACION DE TAPA DEL FLUID END "A" | N20: N/A | O20: 0 | Q20: TAPA DEL FLUID END 3-1/2" | R20: N/A | U20: 1 | V20: UND | W20: FABRICADO | X20: ENTREGA DE MATERIAL FABRICADO EN PROVEEDOR EXTERNO REQUERIDO PARA REPARACION DE BOMBA DE LODO ASOCIADA A EQUIPO
D21: 44810 | H21: TP-DCT-001 | I21: CT | K21: PLANIFICADO | L21: PREVENCION ANTE FUTURAS FALLAS | M21: CERTIFICACION DE COMPONENTE EN TALLER EXTERNO "SEBROMEN,C.A" | N21: GP-CT-2022-013 | O21: 0 | Q21: BOP TIPO CONVI | R21: N/A | S21: TEXAS OIL TOOLS | T21: 153-48329 | U21: 1 | V21: UND | W21: USADO | X21: ENVIO DE COMPONENTE A SERVICIO DE CERTIFICACION EN PROVEEDOR EXTERNO SEGÚN ODS: GP-CL-2022-013 LA MISMA DEBE RETORNAR AL FINALIZAR SERVICIO
D22: 44810 | H22: TP-DCT-001 | I22: CT | K22: PLANIFICADO | L22: PREVENCION ANTE FUTURAS FALLAS | M22: CERTIFICACION DE COMPONENTE EN TALLER EXTERNO "SEBROMEN,C.A" | N22: GP-CT-2022-013 | O22: 0 | Q22: BOP QUARTZ P/N: LE44-X1400B INCLUYE VALVULA 2X2 P/N: BH0006, VALVULA 2X1 P/N: FP10151 Y TEE DE FLUJO | R22: N/A | S22: TEXAS OIL TOOLS | T22: 153-48327 | U22: 1 | V22: UND | W22: USADO | X22: ENVIO DE COMPONENTE A SERVICIO DE CERTIFICACION EN PROVEEDOR EXTERNO SEGÚN ODS: GP-CL-2022-013 LA MISMA DEBE RETORNAR AL FINALIZAR SERVICIO
D23: 44817 | H23: TP-DCT-001 | I23: UNIDAD DE BOMBEO | K23: CORRECTIVO | L23: FUGA DE REFRIGERANTE, EN SELLO DE LA BOMBA DE REFRIGERANTE | M23: INSTALACION DE BOMBA DE REFRIGERANTE REPARADA EN PROVEEDOR EXTERNO "MULTIBOMBAS EL TIGRE C.A" | N23: N/A | O23: 0 | Q23: BOMBA DE AGUA DE CAMION COILED TUBING P/N: 23522721, P/N: 8922383 | R23: N/A | T23: 4260 | U23: 1 | V23: UND | W23: REPARADO | X23: ENTREGA DE COMPONENTE PARA SER INSTALADO EN CAMION DEL EQUIPO COILED TUBING UBICADO EN BASE SAI
D24: 44830 | H24: TP-DCT-001 | I24: CT | K24: PLANIFICADO | L24: ADAPTACION DE HERRAMIENTA WELL-VAC Y SAND-VAC EN CT | M24: ENVIO DE COMPONENTE PARA MECANIZACION EN TALLER EXTERNO "A. MOLINA" | N24: GP-CT-2022-015 | O24: 0 | Q24: ROLL-ON CONECTOR 2-3/8" X 0,185' | R24: N/A | U24: 2 | V24: PZA | W24: NUEVO | X24: ENVIO DE COMPONENTE A PROVEEDOR EXTERNO PARA REALIZAR SERVICIO DE MECANIZADO SEGÚN ODS: GP-CL-2022-015
D25: 44830 | H25: TP-DCT-001 | I25: CT | K25: PLANIFICADO | L25: ADAPTACION DE HERRAMIENTA WELL-VAC Y SAND-VAC EN CT | M25: ENVIO DE COMPONENTE PARA MECANIZACION EN TALLER EXTERNO "A. MOLINA" | N25: GP-CT-2022-015 | O25: 0 | Q25: CROSSOVER PIN TO PIN 2-1/2" | R25: N/A | U25: 1 | V25: PZA | W25: NUEVO | X25: ENVIO DE COMPONENTE A PROVEEDOR EXTERNO PARA REALIZAR SERVICIO DE MECANIZADO SEGÚN ODS: GP-CL-2022-015
D26: 44831 | H26: TP-DCT-001 | I26: UNIDAD DE BOMBEO | K26: CORRECTIVO | L26: FALLA EN SISTEMA ELECTRICO | M26: REEMPLAZO DE FUSIBLE EN PLC DE LA UNIDAD DE BOMBEO | N26: N/A | O26: 0 | Q26: FUSIBLE 250V X 6,3 AMP | R26: 617006 | U26: 1 | V26: UND | W26: NUEVO | X26: ENTREGA DE MATERIAL PARA REEMPLAZO EN PLC DE LA UNIDAD BOMBA DEL EQUIPO COILED TUBING
D27: 44833 | H27: TP-DCT-001 | I27: UNIDAD DE BOMBEO | K27: PREVENTIVO | L27: PREVENCION ANTE FUTURAS FALLAS | M27: REEMPLAZO DE FLUIDO REFRIGERANTE EN UNIDAD DE BOMBEO Y POWER PACK | N27: N/A | O27: 0 | Q27: REFRIGERANTE ANTICORROSIVO ROJO | R27: 1.006.0001.0007 | U27: 170 | V27: LTS | W27: NUEVO | X27: ENTREGA DE MATERIAL REQUERIDO PARA CAMBIO DE REFRIGERANTE EN LA UNIDAD DE BOMBEO DEL EQUIPO COILED TUBING UBICADO EN BASE SAI
D28: 44838 | H28: TP-DCT-001 | I28: CANOA | K28: CORRECTIVO | L28: ADECUACIONES Y REEMPLAZO DE LAMINAS Y FLANGES | M28: ENVIO DE COMPONENTE PARA REPARACION EN BASE TEPECA POR PERSONAL DE FABRICACION | N28: N/A | O28: 0 | Q28: CANOA DE 12 MTS X 3 MTS | R28: N/A | U28: 1 | V28: UND | W28: USADO | X28: ENVIO DE COMPONENTE PARA REPARACION EN TALLER DE FABRICACION BASE TEPECA
D29: 44838 | H29: TP-DCT-001 | I29: POWER PACK | K29: PREVENTIVO | L29: PREVENCION ANTE FUTURAS FALLAS | M29: REEMPLAZO DE FILTROS DE ACEITE DE MOTOR S60 | N29: N/A | O29: 0 | Q29: FILTRO DE ACEITE 51971 / P552100 / ML-25971 | R29: 2.030.0001.0005 | S29: MILLARD | U29: 2 | V29: UND | W29: NUEVO | X29: ENTREGA DE MATERIAL PARA MANTENIMIENTO PREVENTIVO A EQUIPO COILED TUBING (UNIDAD POWER PACK)
D30: 44838 | H30: TP-DCT-001 | I30: POWER PACK | K30: PREVENTIVO | L30: PREVENCION ANTE FUTURAS FALLAS | M30: REEMPLAZO DE FILTRO SECUNDARIO DE COMBUSTIBLE DE MOTOR S60 | N30: N/A | O30: 0 | Q30: FILTRO S. DE COMB. 33120 / P556916 / F3120 | R30: 2.031.0001.0013 | S30: WEB | U30: 1 | V30: UND | W30: NUEVO | X30: ENTREGA DE MATERIAL PARA MANTENIMIENTO PREVENTIVO A EQUIPO COILED TUBING (UNIDAD POWER PACK)
D31: 44838 | H31: TP-DCT-001 | I31: POWER PACK | K31: PREVENTIVO | L31: PREVENCION ANTE FUTURAS FALLAS | M31: REEMPLAZO DE FILTRO PRIMARIO DE COMBUSTIBLE DE MOTOR S60 | N31: N/A | O31: 0 | Q31: FILTRO P. DE COMB. 33118 / P556915 | R31: 33118 | U31: 1 | V31: UND | W31: NUEVO | X31: ENTREGA DE MATERIAL PARA MANTENIMIENTO PREVENTIVO A EQUIPO COILED TUBING (UNIDAD POWER PACK)
D32: 44838 | H32: TP-DCT-001 | I32: POWER PACK | K32: PREVENTIVO | L32: PREVENCION ANTE FUTURAS FALLAS | M32: REEMPLAZO DE FILTRO DE COMBUSTIBLE EN TRAMPA DE AGUA DEL MOTOR S60 | N32: N/A | O32: 0 | Q32: FILTRO TRAMPA DE AGUA 33792 / FC33792 / PP-2020 | R32: 2.031.0001.0013 | U32: 1 | V32: UND | W32: NUEVO | X32: ENTREGA DE MATERIAL PARA MANTENIMIENTO PREVENTIVO A EQUIPO COILED TUBING (UNIDAD POWER PACK)
D33: 44838 | H33: TP-DCT-001 | I33: POWER PACK | K33: PREVENTIVO | L33: PREVENCION ANTE FUTURAS FALLAS | M33: CAMBIO DE ACEITE DE MOTOR S60 | N33: N/A | O33: 0 | Q33: ACEITE DE MOTOR 15W40 | R33: 15W40 | U33: 40 | V33: LTS | W33: NUEVO | X33: ENTREGA DE MATERIAL PARA MANTENIMIENTO PREVENTIVO A EQUIPO COILED TUBING (UNIDAD POWER PACK)
D34: 44838 | H34: TP-DCT-001 | I34: POWER PACK | K34: PREVENTIVO | L34: PREVENCION ANTE FUTURAS FALLAS | M34: REEMPLAZO DE FILTRO DE REFRIGERANTE DEL MOTOR S60 | N34: N/A | O34: 0 | Q34: FILTRO DE RERIGERANTE 23516489 / BW5200 / DBC4088 | R34: N/A | U34: 1 | V34: UND | W34: NUEVO | X34: ,
D35: 44838 | H35: TP-DCT-001 | I35: POWER PACK | K35: PREVENTIVO | L35: PREVENCION ANTE FUTURAS FALLAS | M35: REEMPLAZO DE FILTRO DEL SISTEMA HIDRAULICO DEL POWER PACK | N35: N/A | O35: 0 | Q35: FILTRO HIDRAULICO 51730 / BT8879-MPG / P165659 | R35: N/A | U35: 2 | V35: UND | W35: NUEVO | X35: ENTREGA DE MATERIAL PARA MANTENIMIENTO PREVENTIVO A EQUIPO COILED TUBING (UNIDAD POWER PACK)
D36: 44838 | H36: TP-DCT-001 | I36: POWER PACK | K36: PREVENTIVO | L36: PREVENCION ANTE FUTURAS FALLAS | M36: REEMPLAZO DE CORREA DE FAN DEL MOTOR S60 | N36: N/A | O36: 0 | Q36: CORREA A-68 | R36: 2.013.0001.0087 | U36: 3 | V36: UND | W36: NUEVO | X36: ENTREGA DE MATERIAL PARA MANTENIMIENTO PREVENTIVO A EQUIPO COILED TUBING (UNIDAD POWER PACK)
D37: 44838 | H37: TP-DCT-001 | I37: POWER PACK | K37: PREVENTIVO | L37: PREVENCION ANTE FUTURAS FALLAS | M37: REEMPLAZO DE CORREA DE ALTERNADOR DEL MOTOR S60 | N37: N/A | O37: 0 | Q37: CORREA PARA MOTOR DETROIT S60 N/P: 23520032 | R37: N/A | U37: 1 | V37: UND | W37: NUEVO | X37: ENTREGA DE MATERIAL PARA MANTENIMIENTO PREVENTIVO A EQUIPO COILED TUBING (UNIDAD POWER PACK)
D38: 44838 | H38: TP-DCT-001 | I38: POWER PACK | K38: PREVENTIVO | L38: PREVENCION ANTE FUTURAS FALLAS | M38: CAMBIO DE ACEITE DEL SISTEMA HIDRAULICO DEL POWER PACK | N38: N/A | O38: 0 | Q38: ACEITE HIDRAULICO ISO-68 | R38: ISO68 | U38: 695 | V38: LTS | W38: NUEVO | X38: ENTREGA DE MATERIAL PARA MANTENIMIENTO PREVENTIVO A EQUIPO COILED TUBING (UNIDAD POWER PACK)
D39: 44839 | H39: TP-DCT-001 | I39: UNIDAD DE BOMBEO | K39: PREVENTIVO | L39: PREVENCION ANTE FUTURAS FALLAS | M39: REEMPLAZO DE FILTROS EN MOTOR "A" Y "B" | N39: N/A | O39: 0 | Q39: FILTRO DE ACEITE 51971 / P552100 / ML-25971 | R39: 2.030.0001.0005 | S39: MILLARD | U39: 4 | V39: UND | W39: NUEVO | X39: ENTREGA DE MATERIAL PARA MANTENIMIENTO PREVENTIVO A EQUIPO COILED TUBING (UNIDAD DE BOMBEO)
D40: 44839 | H40: TP-DCT-001 | I40: UNIDAD DE BOMBEO | K40: PREVENTIVO | L40: PREVENCION ANTE FUTURAS FALLAS | M40: CAMBIO DE FILTRO DE COMBUSTIBLE DE MOTOR "A" Y "B" | N40: N/A | O40: 0 | Q40: FILTRO DE COMB. TRAMPA DE AGUA 33651 / MF-61492 / WC-7772A | R40: 2.001.0006.0056 | S40: MILLARD | U40: 2 | V40: UND | W40: NUEVO | X40: ENTREGA DE MATERIAL PARA MANTENIMIENTO PREVENTIVO A EQUIPO COILED TUBING (UNIDAD DE BOMBEO)
D41: 44839 | H41: TP-DCT-001 | I41: UNIDAD DE BOMBEO | K41: PREVENTIVO | L41: PREVENCION ANTE FUTURAS FALLAS | M41: CAMBIO DE ACEITE A MOTOR "A" Y "B" | N41: N/A | O41: 0 | Q41: ACEITE DE MOTOR 15W40 | R41: 15W40 | U41: 80 | V41: LTS | W41: NUEVO | X41: ENTREGA DE MATERIAL PARA MANTENIMIENTO PREVENTIVO A EQUIPO COILED TUBING (UNIDAD DE BOMBEO)
D42: 44839 | H42: TP-DCT-001 | I42: UNIDAD DE BOMBEO | K42: RUTINARIO | L42: HIGIENE Y SEGURIDAD | M42: LIMPIEZA DE EQUIPO Y VALVULAS | N42: N/A | O42: 0 | Q42: CEPILLO DE ALAMBRE | R42: N/A | U42: 1 | V42: UND | W42: NUEVO | X42: ENTREGA DE MATERIAL PARA MANTENIMIENTO PREVENTIVO A EQUIPO COILED TUBING (UNIDAD DE BOMBEO)
D43: 44839 | H43: TP-DCT-001 | I43: UNIDAD DE BOMBEO | K43: PREVENTIVO | L43: PREVENCION ANTE FUTURAS FALLAS | M43: CAMBIO DE ACEITE DE SISTEMA HIDRAULICO DE LA UNIDAD DE BOMBEO | N43: N/A | O43: 0 | Q43: ACEITE HIDRAULICO ISO-68 | R43: ISO68 | U43: 541 | V43: LTS | W43: NUEVO | X43: ENTREGA DE MATERIAL PARA MANTENIMIENTO PREVENTIVO A EQUIPO COILED TUBING (UNIDAD DE BOMBEO)
...

Sheet Hoja5
A3: TIPO DE MTTO | B3: FRECUENCIA
A4: CORRECTIVO | B4: 22
A5: N/A | B5: 17 | D5: CANT | E5: (Varios elementos)
A6: PLANIFICADO | B6: 57 | H6: UNIDAD | I6: FRECUENCIA
A7: PREVENTIVO | B7: 30 | D7: Etiquetas de fila | E7: Suma de CANT | H7: MTTO | I7: 1
A8: RUTINARIO | B8: 35 | D8: ACEITE DE HIDRAULICO ISO68 (USADO) | E8: 1083 | H8: PDV-181 | I8: 1
A9: Total general | B9: 161 | D9: ACEITE DE MOTOR 15W40 | E9: 325 | H9: SAI-205 | I9: 1
D10: ACEITE DE MOTOR 15W40 (USADO) | E10: 20 | H10: SAI-215 | I10: 2
D11: ACEITE DE TRANSMISION 80W90 | E11: 412.5 | H11: TP-552 | I11: 1
D12: ACEITE HIDRAULICO ISO-68 | E12: 1256 | H12: TP-554 | I12: 2
A13: Etiquetas de fila | B13: Cuenta de CAUSA O FALLA | D13: ARANDELA PLANA | E13: 15 | H13: TP-CH-018 | I13: 1
A14: FABRICADO | B14: 3 | D14: ESPARRAGO 11907-83 (5/8" X 3-1/2") | E14: 20 | H14: TP-DCT-001 | I14: 149
A15: NUEVO | B15: 119 | D15: GRASA SWEPCO 222 | E15: 20 | H15: TP-MT-017 | I15: 2
A16: REPARADO | B16: 4 | D16: REFRIGERANTE ANTICORROSIVO ROJO | E16: 170 | H16: TP-V-007 | I16: 1
A17: USADO | B17: 35 | D17: TUERCA PARA ESPARRAGO 5/8 | E17: 25 | H17: Total general | I17: 161
A18: Total general | B18: 161 | D18: Total general | E18: 3346.5

Sheet REP
B2: RESUMEN DE MATERIALES
B5: # | C5: DESCRIPCION | D5: CANT. REQ. | E5: STOCK INICIAL | F5: IN | G5: OUT | H5: CANT. DISP. | I5: UND | J5: OBSERVACION
B6: 1 | C6: ACEITE DE MOTOR 15W40 | D6: 118 | E6: =SUMIF(INV.!$D$6:$D$1000,REP!$C$6:$C$1000,INV.!$F$6:$F$1000) -> 0 | F6: =SUMIF(IN!$L$6:$L$1000,REP!$C$6:$C$998,IN!$Q$6:$Q$1000) -> 412.5 | G6: =SUMIF(OUT!$Q$7:$Q$1000,REP!C6:$C$998,OUT!$U$7:$U$1000) -> 333 | H6: =E6+F6-G6 -> 79.5 | I6: LT
B7: 2 | C7: FILTRO DE AIRE P181099 | D7: 2 | E7: =SUMIF(INV.!$D$6:$D$1000,REP!$C$6:$C$1000,INV.!$F$6:$F$1000) -> 0 | F7: =SUMIF(IN!$L$6:$L$1000,REP!$C$6:$C$998,IN!$Q$6:$Q$1000) -> 0 | G7: =SUMIF(OUT!$Q$7:$Q$1000,REP!C7:$C$998,OUT!$U$7:$U$1000) -> 0 | H7: =E7+F7-G7 -> 0 | I7: PZA
B8: 3 | C8: FILTRO DE ACEITE 51971 / P552100 / ML-25971 | D8: 6 | E8: =SUMIF(INV.!$D$6:$D$1000,REP!$C$6:$C$1000,INV.!$F$6:$F$1000) -> 0 | F8: =SUMIF(IN!$L$6:$L$1000,REP!$C$6:$C$998,IN!$Q$6:$Q$1000) -> 8 | G8: =SUMIF(OUT!$Q$7:$Q$1000,REP!C8:$C$998,OUT!$U$7:$U$1000) -> 6 | H8: =E8+F8-G8 -> 2 | I8: PZA
B9: 4 | C9: FILTRO DE COMB. TRAMPA DE AGUA 33651 / MF-61492 / WC-7772A | D9: 2 | E9: =SUMIF(INV.!$D$6:$D$1000,REP!$C$6:$C$1000,INV.!$F$6:$F$1000) -> 0 | F9: =SUMIF(IN!$L$6:$L$1000,REP!$C$6:$C$998,IN!$Q$6:$Q$1000) -> 2 | G9: =SUMIF(OUT!$Q$7:$Q$1000,REP!C9:$C$998,OUT!$U$7:$U$1000) -> 2 | H9: =E9+F9-G9 -> 0 | I9: PZA
B10: 5 | C10: ARRANQUE NEUMATICO, MOD:150BMP88RS4-200 | D10: 2 | E10: =SUMIF(INV.!$D$6:$D$1000,REP!$C$6:$C$1000,INV.!$F$6:$F$1000) -> 0 | F10: =SUMIF(IN!$L$6:$L$1000,REP!$C$6:$C$998,IN!$Q$6:$Q$1000) -> 0 | G10: =SUMIF(OUT!$Q$7:$Q$1000,REP!C10:$C$998,OUT!$U$7:$U$1000) -> 0 | H10: =E10+F10-G10 -> 0 | I10: PZA
B11: 6 | C11: CORREA A-47 | D11: 6 | E11: =SUMIF(INV.!$D$6:$D$1000,REP!$C$6:$C$1000,INV.!$F$6:$F$1000) -> 0 | F11: =SUMIF(IN!$L$6:$L$1000,REP!$C$6:$C$998,IN!$Q$6:$Q$1000) -> 12 | G11: =SUMIF(OUT!$Q$7:$Q$1000,REP!C11:$C$998,OUT!$U$7:$U$1000) -> 4 | H11: =E11+F11-G11 -> 8 | I11: PZA
B12: 7 | C12: CORREA A-68 | D12: 9 | E12: =SUMIF(INV.!$D$6:$D$1000,REP!$C$6:$C$1000,INV.!$F$6:$F$1000) -> 0 | F12: =SUMIF(IN!$L$6:$L$1000,REP!$C$6:$C$998,IN!$Q$6:$Q$1000) -> 27 | G12: =SUMIF(OUT!$Q$7:$Q$1000,REP!C12:$C$998,OUT!$U$7:$U$1000) -> 9 | H12: =E12+F12-G12 -> 18 | I12: PZA
B13: 8 | C13: BOMBA DE AGUA P/N;23522721 | D13: 3 | E13: =SUMIF(INV.!$D$6:$D$1000,REP!$C$6:$C$1000,INV.!$F$6:$F$1000) -> 0 | F13: =SUMIF(IN!$L$6:$L$1000,REP!$C$6:$C$998,IN!$Q$6:$Q$1000) -> 0 | G13: =SUMIF(OUT!$Q$7:$Q$1000,REP!C13:$C$998,OUT!$U$7:$U$1000) -> 0 | H13: =E13+F13-G13 -> 0 | I13: PZA
B14: 9 | C14: ALTERNADOR 27V DC 70A | D14: 2 | E14: =SUMIF(INV.!$D$6:$D$1000,REP!$C$6:$C$1000,INV.!$F$6:$F$1000) -> 0 | F14: =SUMIF(IN!$L$6:$L$1000,REP!$C$6:$C$998,IN!$Q$6:$Q$1000) -> 0 | G14: =SUMIF(OUT!$Q$7:$Q$1000,REP!C14:$C$998,OUT!$U$7:$U$1000) -> 0 | H14: =E14+F14-G14 -> 0 | I14: PZA
B15: 10 | C15: COMPRESOR NEUMATICO TUFLO 550 | D15: 3 | E15: =SUMIF(INV.!$D$6:$D$1000,REP!$C$6:$C$1000,INV.!$F$6:$F$1000) -> 0 | F15: =SUMIF(IN!$L$6:$L$1000,REP!$C$6:$C$998,IN!$Q$6:$Q$1000) -> 0 | G15: =SUMIF(OUT!$Q$7:$Q$1000,REP!C15:$C$998,OUT!$U$7:$U$1000) -> 0 | H15: =E15+F15-G15 -> 0 | I15: PZA
B16: 11 | C16: BOMBA DE TRANSFERENCIA P/N:23532981 | D16: 2 | E16: =SUMIF(INV.!$D$6:$D$1000,REP!$C$6:$C$1000,INV.!$F$6:$F$1000) -> 0 | F16: =SUMIF(IN!$L$6:$L$1000,REP!$C$6:$C$998,IN!$Q$6:$Q$1000) -> 0 | G16: =SUMIF(OUT!$Q$7:$Q$1000,REP!C16:$C$998,OUT!$U$7:$U$1000) -> 0 | H16: =E16+F16-G16 -> 0 | I16: PZA
B17: 12 | C17: ECU P/N: 6DD4408E09 | D17: 2 | E17: =SUMIF(INV.!$D$6:$D$1000,REP!$C$6:$C$1000,INV.!$F$6:$F$1000) -> 0 | F17: =SUMIF(IN!$L$6:$L$1000,REP!$C$6:$C$998,IN!$Q$6:$Q$1000) -> 0 | G17: =SUMIF(OUT!$Q$7:$Q$1000,REP!C17:$C$998,OUT!$U$7:$U$1000) -> 0 | H17: =E17+F17-G17 -> 0 | I17: PZA
... B118: 113 | C118: MANOMETRO DE 2" 0-6000 PSI CONEXIÓN POSTERIOR DE 1/4" NPT | D118: 0 | E118: =SUMIF(INV.!$D$6:$D$1000,REP!$C$6:$C$1000,INV.!$F$6:$F$1000) -> 0 | F118: =SUMIF(IN!$L$6:$L$1000,REP!$C$6:$C$998,IN!$Q$6:$Q$1000) -> 6 | G118: =SUMIF(OUT!$Q$7:$Q$1000,REP!C118:$C$998,OUT!$U$7:$U$1000) -> 6 | H118: =E118+F118-G118 -> 0 | I118: PZA

Sheet INV.
B2: Inventario Coiled Tubing (FROM MERIDIAN)
B5: P/N | C5: Ubicación | D5: Descripcion | E5: UM | F5: Cantidad | G5: Observaciones
B6: N/A | C6: AREA EXTERNA | D6: UNIDAD DE COILED TUBING (POWER PACK) | E6: UND | F6: 1
B7: N/A | C7: AREA EXTERNA | D7: UNIDAD DE COILED TUBING (REEL) | E7: UND | F7: 1
B8: N/A | C8: AREA EXTERNA | D8: UNIDAD DE BOMBEO MARCA JEREL | E8: UND | F8: 1
B9: N/A | C9: AREA EXTERNA | D9: TUBERIA 2-3/8" OD, .175 WALL THICKNESS | E9: FT | F9: 12000
B10: N/A | C10: AREA EXTERNA | D10: INJECTOR SERIAL # IWOO-051 ARCH SERAIL # AWOO-060 | E10: UND | F10: 1
B11: N/A | C11: AREA EXTERNA | D11: CONTADOR | E11: UND | F11: 1
B12: N/A | C12: AREA EXTERNA | D12: BOP EH44 QUAD NACE 2.38 H2S M60TOT-EH44L613X | E12: UND | F12: 1
B13: N/A | C13: GALPON 2 | D13: BOP 4.06 10M COMBI OXS H2S 2.38 M60TOT-EH44N612X
B14: N/A | C14: GALPON 2 | D14: MANGUERAS DE GOMAS DE 4" X 20 FT (SUCCION) | E14: UND | F14: 7
B15: N/A | C15: GALPON 2 | D15: MANGUERAS DE GOMAS DE 4" X 20 FT (DESCARGA) | E15: UND | F15: 5
B16: N/A | C16: GALPON 2 | D16: MANGUERAS DE GOMAS DE 4" X 15 FT (SUCCION) | E16: UND | F16: 4
B17: N/A | C17: GALPON 2 | D17: MANGUERAS DE HIERRO DE 2" X 10 FT (ROJAS) | E17: UND | F17: 7
B18: N/A | C18: GALPON 2 | D18: MANGUERAS DE HIERRO DE 2" X 6 FT (ROJAS) | E18: UND | F18: 9 | G18: DEBIERON LLEGAR 11 UND
B19: N/A | C19: GALPON 2 | D19: MANGUERAS DE HIERRO DE 2" X 5 FT (ROJAS) | E19: UND | F19: 2
B20: N/A | C20: GALPON 2 | D20: MANGUERAS DE HIERRO DE 2" X 4 FT (ROJAS) | E20: UND | F20: 1
B21: N/A | C21: GALPON 2 | D21: MANGUERAS DE HIERRO DE 2" X 3 FT (ROJAS) | E21: UND | F21: 4
B22: N/A | C22: GALPON 2 | D22: MANGUERAS DE HIERRO DE 2" X 2 FT (ROJAS) | E22: UND | F22: 2
B23: N/A | C23: GALPON 2 | D23: MANGUERAS DE HIERRO DE 2" X 10 FT (VERDES) | E23: UND | F23: 2
B24: N/A | C24: GALPON 2 | D24: MANGUERAS DE HIERRO DE 2" X 6 FT (VERDES) | E24: UND | F24: 4
B25: N/A | C25: GALPON 2 | D25: MANGUERAS DE HIERRO DE 2" X 4 FT (VERDES) | E25: UND | F25: 2
B26: N/A | C26: GALPON 2 | D26: MANGUERAS DE HIERRO DE 2" X 3 FT (VERDES) | E26: UND | F26: 1
B27: N/A | C27: GALPON 2 | D27: MANGUERA DE HIERRO 2 (HOSE STEEL) | E27: UND | F27: 1
B28: N/A | C28: GALPON 2 | D28: ADPT FLG 2,00 10M H2S BX-152 1502 | E28: UND | F28: 1
B29: N/A | C29: GALPON 2 | D29: SB RISER: 4.06 10K H2S BX-155 - SERIAL 153-48338 | E29: UND | F29: 1
B30: N/A | C30: GALPON 2 | D30: ADPT SPOOL: 4.06 10M H2S BX-155 X 3,06 BX-154 | E30: UND | F30: 1
B31: N/A | C31: GALPON 2 | D31: ADPTR SPL: 5.12 10M BX-169 X 4.06 10M BX-155 | E31: UND | F31: 1
B32: N/A | C32: CAJA DE HERRAMIENTAS DEL EQUIPO | D32: TEE 4" | E32: UND | F32: 3 | G32: 1 UND EN GALPON 2
B33: N/A | C33: CAJA DE HERRAMIENTAS DEL EQUIPO | D33: CODOS 4" | E33: UND | F33: 3
B34: N/A | C34: CAJA DE HERRAMIENTAS DEL EQUIPO | D34: CONEXIONES DE HIERRO CON VALVULA MARIPOSA DE 4" | E34: UND | F34: 1
B35: N/A | C35: CAJA DE HERRAMIENTAS DEL EQUIPO | D35: YEE 2" NARANJA | E35: UND | F35: 2
B36: N/A | C36: CAJA DE HERRAMIENTAS DEL EQUIPO | D36: YEE 2" R/F/F ROJAS | E36: UND | F36: 2
B37: N/A | C37: CAJA DE HERRAMIENTAS DEL EQUIPO | D37: TEE 2" R/F/F ROJAS | E37: UND | F37: 3
B38: N/A | C38: CAJA DE HERRAMIENTAS DEL EQUIPO | D38: TEE 2" R/R/F ROJAS | E38: UND | F38: 1
B39: N/A | C39: CAJA DE HERRAMIENTAS DEL EQUIPO | D39: UNION 2" R/R ROJAS | E39: UND | F39: 2
B40: N/A | C40: CAJA DE HERRAMIENTAS DEL EQUIPO | D40: UNION 2" F/F ROJAS | E40: UND | F40: 3
B41: N/A | C41: CAJA DE HERRAMIENTAS DEL EQUIPO | D41: VALVULA 2 X 1 R/F ROJAS | E41: UND | F41: 5
B42: N/A | C42: CAJA DE HERRAMIENTAS DEL EQUIPO | D42: VALVULA 2 X 1 R/F VERDES | E42: UND | F42: 3
B43: N/A | C43: CAJA DE HERRAMIENTAS DEL EQUIPO | D43: VALVULA 2 X 1 R/F NARANJA | E43: UND | F43: 1
...

Sheet Indicadores
D2: DASHBOARD TRIMESTRAL (DPTO. DE COILED TUBING)
