Workbook
Name BLOQUE8: Tabla9[]
Name BLOQUE8: Tabla9[]
Name BLOQUE8: Tabla9[]
Name BLOQUE8: [1]!Tabla9[#Data]
Name BLOQUE8: Tabla9[]
Name BLOQUE8: Tabla9[]
Name BLOQUE8: [1]!Tabla9[#Data]
Name BLOQUE8: Tabla9[]
Name BLOQUE8: Tabla921[]
Name BLOQUE8: Tabla9[]
Name BLOQUE8: Tabla92122[]
Name BLOQUE8: Tabla9[]
Name BLOQUE8: Tabla9[]
Name BLOQUE8: Tabla9[]
Name DIEZPUNTOUNO: LEJOS19[]
Name KARIÑASUR: Tabla8[]
Name KARIÑASUR: Tabla8[]
Name KARIÑASUR: Tabla8[]
Name KARIÑASUR: [1]!Tabla8[#Data]
Name KARIÑASUR: Tabla8[]
Name KARIÑASUR: Tabla8[]
Name KARIÑASUR: [1]!Tabla8[#Data]
Name KARIÑASUR: Tabla8[]
Name KARIÑASUR: Tabla8[]
Name KARIÑASUR: Tabla8[]
Name KARIÑASUR: Tabla8[]
Name KARIÑASUR: Tabla8[]
Name KARIÑASUR: Tabla8[]
Name KARIÑASUR: Tabla8[]
Name MEREY20: Tabla7[]
Name MEREY20: Tabla7[]
Name MEREY20: Tabla7[]
Name MEREY20: [1]!Tabla7[#Data]
Name MEREY20: Tabla7[]
Name MEREY20: Tabla7[]
Name MEREY20: [1]!Tabla7[#Data]
Name MEREY20: Tabla7[]
Name MEREY20: Tabla7[]
Name MEREY20: Tabla7[]
Name MEREY20: Tabla7[]
Name MEREY20: Tabla7[]
Name MEREY20: Tabla7[]
Name MEREY20: Tabla7[]
Name MEREY29: Tabla6[]
Name MEREY29: Tabla6[]
Name MEREY29: Tabla6[]
Name MEREY29: [1]!Tabla6[#Data]
Name MEREY29: Tabla6[]
Name MEREY29: Tabla6[]
Name MEREY29: [1]!Tabla6[#Data]
Name MEREY29: Tabla6[]
Name MEREY29: Tabla6[]
Name MEREY29: Tabla6[]
Name MEREY29: Tabla6[]
Name MEREY29: Tabla6[]
Name MEREY29: Tabla6[]
Name MEREY29: Tabla6[]
Name NORTEBARE: Tabla921[]
Name Oeste: OESTE1[]
Name Oeste: OESTE1[]

Sheet Pinos 1
E3: Calidad | AF3: CODIGO: FO-CA-GE-02-E
AF4: REVISION: 00
E5: Máster de Inspección | AF5: FECHA DE EMISIÓN: 28-02-2024
B8: Nombre del Proyecto: | E8: "Mantenimiento En El Sistema Eléctrico De Distribución 13.8 Kv De La División Ayacucho" | Y8: Nro. de Contrato: | AB8: 4600135303
B9: Disciplina | E9: Electricidad | Y9: Ubicación: | AB9: División Ayacucho
B10: DATOS | F10: MANTENIMIENTO PREDICTIVO EJECUTADO | AD10: MANTENIMIENTO PREVENTIVO EJECUTADO
F12: VISUAL | T12: TERMOGRAFÍA | Y12: ULTRASONIDO | AD12: INTERVENCIÓN
F13: Componentes
B14: Frente | C14: Circuito | D14: Nro. De poste | E14: Descripción | F14: Fecha V | G14: Aislador de Espiga (AE) | H14: Aislador Polimericos (APT ) 34,5 Kv | I14: Aislador de Cadena (Ac) | J14: Aislador Polimericos (APs ) 69 Kv | K14: Cortacorriente (CC) | L14: Abierto | M14: Cerrado | N14: Pararrayos (P) | O14: Grapa ( G ) | P14: Seccionador (SM) | Q14: Abierto 2 | R14: Cerrado3 | S14: Falla Detectada V | T14: Fecha T | U14: Ejecutado T | V14: Puntos de Termografía | W14: Falla Detectada T | X14: Observación T | Y14: Fecha UT | Z14: Ejecutado UT | AA14: Puntos de Ultrasonido | AB14: Falla Detectada UT | AC14: Observación UT | AD14: Fecha | AE14: Ejecutado MTTO | AF14: Observación
B15: U.P. PESADO | C15: PINOS 1 | D15: 1 | E15: Amarre Terminal | I15: 3 | N15: 6 | O15: 3 | P15: 3 | S15: NIVEL 3: Revisar copa terminal | T15: 45313 | U15: X | V15: 12 | Y15: 45313 | Z15: X | AA15: 15 | AB15: EFECTO CORONA EN SM FASE A Y C / P FASE B Y C / AC FASE B Y C / SE DESINTALARON 7 GRAPAS A COMPRESION Y 7 BARRACUDAS | AD15: 45328 | AE15: Ejecutada
B16: U.P. PESADO | C16: PINOS 1 | D16: 2 | E16: PASE | G16: 3 | Y16: 45313 | Z16: X | AA16: 3
B17: U.P. PESADO | C17: PINOS 1 | D17: 3 | E17: PASE | G17: 3 | N17: 3 | Y17: 45313 | Z17: X | AA17: 6
B18: U.P. PESADO | C18: PINOS 1 | D18: 4 | E18: AMARRE | G18: 3 | I18: 6 | O18: 6 | T18: 45313 | U18: X | V18: 6 | Y18: 45313 | Z18: X | AA18: 9
B19: U.P. PESADO | C19: PINOS 1 | D19: 5 | E19: AMARRE 90° | G19: 3 | I19: 6 | N19: 3 | O19: 3 | T19: 45313 | U19: X | V19: 3 | Y19: 45313 | Z19: X | AA19: 12
B20: U.P. PESADO | C20: PINOS 1 | D20: 6 | E20: PASE | G20: 3 | Y20: 45313 | Z20: X | AA20: 3
B21: U.P. PESADO | C21: PINOS 1 | D21: 7 | E21: PASE | G21: 3 | N21: 3 | Y21: 45313 | Z21: X | AA21: 6
B22: U.P. PESADO | C22: PINOS 1 | D22: 8 | E22: PASE | G22: 3 | Y22: 45313 | Z22: X | AA22: 3
B23: U.P. PESADO | C23: PINOS 1 | D23: 9 | E23: AMARRE | G23: 1 | I23: 6 | N23: 3 | O23: 3 | T23: 45313 | U23: X | V23: 3 | Y23: 45313 | Z23: X | AA23: 10
B24: U.P. PESADO | C24: PINOS 1 | D24: 10 | E24: PASE | G24: 3 | Y24: 45313 | Z24: X | AA24: 3
B25: U.P. PESADO | C25: PINOS 1 | D25: 11 | E25: PASE | G25: 3 | N25: 3 | Y25: 45313 | Z25: X | AA25: 6
B26: U.P. PESADO | C26: PINOS 1 | D26: 12 | E26: PASE | G26: 3 | S26: NIVEL 3: Fase A fogoneada | Y26: 45313 | Z26: X | AA26: 3 | AD26: 45368 | AE26: Ejecutada
B27: U.P. PESADO | C27: PINOS 1 | D27: 13 | E27: PASE | G27: 3 | N27: 3 | Y27: 45313 | Z27: X | AA27: 6
B28: U.P. PESADO | C28: PINOS 1 | D28: 14 | E28: AMARRE CON DER 90° | G28: 2 | I28: 9 | O28: 10 | T28: 45313 | U28: X | V28: 10 | Y28: 45313 | Z28: X | AA28: 11
B29: U.P. PESADO | C29: PINOS 1 | D29: 15 | E29: AMARRE TERMINAL | I29: 3 | P29: 3 | Q29: X | T29: 45313 | U29: X | V29: 3 | Y29: 45313 | Z29: X | AA29: 3
B30: U.P. PESADO | C30: PINOS 1 | D30: 16 | E30: PASE | G30: 3 | N30: 3 | Y30: 45313 | Z30: X | AA30: 6
B31: U.P. PESADO | C31: PINOS 1 | D31: 17 | E31: PASE | G31: 3 | Y31: 45313 | Z31: X | AA31: 3
B32: U.P. PESADO | C32: PINOS 1 | D32: 18 | E32: AMARRE | G32: 1 | I32: 6 | N32: 3 | O32: 6 | T32: 45313 | U32: X | V32: 6 | Y32: 45313 | Z32: X | AA32: 10
B33: U.P. PESADO | C33: PINOS 1 | D33: 19 | E33: PASE | G33: 3 | Y33: 45313 | Z33: X | AA33: 3
B34: U.P. PESADO | C34: PINOS 1 | D34: 20 | E34: PASE | G34: 6 | S34: NIVEL 2: Falta varilla de armado | Y34: 45313 | Z34: X | AA34: 6
B35: U.P. PESADO | C35: PINOS 1 | D35: 21 | E35: PASE CON DER 90° | G35: 3 | H35: 3 | O35: 3 | P35: 3 | T35: 45313 | U35: X | V35: 12 | Y35: 45313 | Z35: X | AA35: 12
B36: U.P. PESADO | C36: PINOS 1 | D36: 22 | E36: AMARRE 45° | G36: 2 | H36: 3 | I36: 3 | O36: 3 | T36: 45313 | U36: X | V36: 3 | Y36: 45313 | Z36: X | AA36: 8
B37: U.P. PESADO | C37: PINOS 1 | D37: 23 | E37: AMARRE 45º | G37: 2 | I37: 6 | N37: 3 | O37: 3 | T37: 45313 | U37: X | V37: 3 | Y37: 45313 | Z37: X | AA37: 11
B38: U.P. PESADO | C38: PINOS 1 | D38: 24 | E38: PASE | G38: 3 | Y38: 45313 | Z38: X | AA38: 3
B39: U.P. PESADO | C39: PINOS 1 | D39: 25 | E39: AMARRE 45º | G39: 2 | I39: 6 | O39: 3 | T39: 45313 | U39: X | V39: 3 | Y39: 45313 | Z39: X | AA39: 8
B40: U.P. PESADO | C40: PINOS 1 | D40: 26 | E40: AMARRE 45º | G40: 2 | I40: 6 | O40: 3 | T40: 45313 | U40: X | V40: 3 | Y40: 45313 | Z40: X | AA40: 8
B41: U.P. PESADO | C41: PINOS 1 | D41: 27 | E41: PASE | G41: 3 | Y41: 45313 | Z41: X | AA41: 3
B42: U.P. PESADO | C42: PINOS 1 | D42: 28 | E42: PASE | G42: 3 | K42: 3 | O42: 3 | T42: 45313 | U42: X | V42: 6 | Y42: 45313 | Z42: X | AA42: 6
B43: U.P. PESADO | C43: PINOS 1 | D43: 29 | E43: PASE | G43: 3 | K43: 3 | O43: 3 | T43: 45313 | U43: X | V43: 6 | Y43: 45313 | Z43: X | AA43: 6
B44: U.P. PESADO | C44: PINOS 1 | D44: 30 | E44: PASE | G44: 3 | K44: 3 | O44: 3 | T44: 45313 | U44: X | V44: 12 | Y44: 45313 | Z44: X | AA44: 6
B45: U.P. PESADO | C45: PINOS 1 | D45: 31 | E45: PASE | G45: 3 | K45: 3 | O45: 3 | T45: 45313 | U45: X | V45: 6 | Y45: 45313 | Z45: X | AA45: 6
...

Sheet Pinos 2
E3: Calidad | AF3: CODIGO: FO-CA-GE-02-E
AF4: REVISION: 00
E5: Máster de Inspección | AF5: FECHA DE EMISIÓN: 28-02-2024
B8: Nombre del Proyecto: | E8: "Mantenimiento En El Sistema Eléctrico De Distribución 13.8 Kv De La División Ayacucho" | Y8: Nro. de Contrato: | AB8: 4600135303
B9: Disciplina | E9: Electricidad | Y9: Ubicación: | AB9: División Ayacucho
B10: DATOS | F10: MANTENIMIENTO PREDICTIVO EJECUTADO | AD10: MANTENIMIENTO PREVENTIVO EJECUTADO
F12: VISUAL | T12: TERMOGRAFÍA | Y12: ULTRASONIDO | AD12: INTERVENCIÓN
F13: Componentes
B14: Frente | C14: Circuito | D14: Nro. De poste | E14: Descripción | F14: Fecha V | G14: Aislador de Espiga (AE) | H14: Aislador Polimericos (APT ) 34,5 Kv | I14: Aislador de Cadena (Ac) | J14: Aislador Polimericos (APs ) 69 Kv | K14: Cortacorriente (CC) | L14: Abierto | M14: Cerrado | N14: Pararrayos (P) | O14: Grapa ( G ) | P14: Seccionador (SM) | Q14: Abierto 2 | R14: Cerrado3 | S14: Falla Detectada V | T14: Fecha T | U14: Ejecutado T | V14: Puntos de Termografía | W14: Falla Detectada T | X14: Observación T | Y14: Fecha UT | Z14: Ejecutado UT | AA14: Puntos de Ultrasonido | AB14: Falla Detectada UT | AC14: Observación UT | AD14: Fecha | AE14: Ejecutado MTTO | AF14: Observación
B15: U.P. PESADO | C15: PINOS 2 | D15: 1 | E15: Amarre Terminal | I15: 3 | N15: 3 | O15: 5 | P15: 3 | T15: 45270 | U15: X | V15: 8 | Y15: 45270 | Z15: X | AA15: 13
B16: U.P. PESADO | C16: PINOS 2 | D16: 2 | E16: Pase | G16: 3 | Y16: 45270 | Z16: X | AA16: 3
B17: U.P. PESADO | C17: PINOS 2 | D17: 3 | E17: Pase | G17: 3 | N17: 3 | Y17: 45270 | Z17: X | AA17: 6
B18: U.P. PESADO | C18: PINOS 2 | D18: 4 | E18: Amarre | G18: 3 | I18: 6 | N18: 3 | O18: 3 | T18: 45270 | U18: X | V18: 3 | Y18: 45270 | Z18: X | AA18: 12
B19: U.P. PESADO | C19: PINOS 2 | D19: 5 | E19: Amarre a 90º | G19: 3 | I19: 6 | K19: 2 | O19: 10 | T19: 45270 | U19: X | V19: 12 | Y19: 45270 | Z19: X | AA19: 11 | AB19: NIVEL 3: FASE "C" ALTOS DECIBELES | AD19: 45337 | AE19: Ejecutada
B20: U.P. PESADO | C20: PINOS 2 | D20: 6 | E20: Amarre | I20: 6 | N20: 3 | O20: 2 | P20: 3 | S20: NIVEL 3: 3 AC DAÑÁDAS FASE "A-B-C", SM FASE "C" DESCONECTADO Y FASE "A Y B" | T20: 45270 | U20: X | V20: 8 | Y20: 45270 | Z20: X | AA20: 13 | AB20: NIVEL 3: EFECTO CORONA | AD20: 45337 | AE20: Ejecutada
B21: U.P. PESADO | C21: PINOS 2 | D21: 7 | E21: Pase | G21: 3 | N21: 3 | Y21: 45270 | Z21: X | AA21: 6
B22: U.P. PESADO | C22: PINOS 2 | D22: 8 | E22: Pase | G22: 3 | Y22: 45270 | Z22: X | AA22: 3
B23: U.P. PESADO | C23: PINOS 2 | D23: 9 | E23: Pase | G23: 3 | N23: 3 | Y23: 45270 | Z23: X | AA23: 6
B24: U.P. PESADO | C24: PINOS 2 | D24: 10 | E24: Pase | G24: 3 | Y24: 45270 | Z24: X | AA24: 3
B25: U.P. PESADO | C25: PINOS 2 | D25: 11 | E25: Amarre | G25: 1 | I25: 6 | N25: 3 | O25: 3 | T25: 45270 | U25: X | V25: 3 | Y25: 45270 | Z25: X | AA25: 10
B26: U.P. PESADO | C26: PINOS 2 | D26: 12 | E26: Pase | G26: 3 | Y26: 45270 | Z26: X | AA26: 3
B27: U.P. PESADO | C27: PINOS 2 | D27: 13 | E27: Pase | G27: 3 | N27: 3 | S27: NIVEL 3: FASE "A" DAÑADA | Y27: 45270 | Z27: X | AA27: 6 | AD27: 45373 | AE27: Ejecutada
B28: U.P. PESADO | C28: PINOS 2 | D28: 14 | E28: Pase con deriv a 45º | G28: 3 | H28: 3 | O28: 20 | T28: 45270 | U28: X | V28: 20 | Y28: 45270 | Z28: X | AA28: 6
B29: U.P. PESADO | C29: PINOS 2 | D29: 15 | E29: Pase con deriv a 45º | H29: 3 | P29: 3 | T29: 45270 | U29: X | V29: 3 | Y29: 45270 | Z29: X | AA29: 6
B30: U.P. PESADO | C30: PINOS 2 | D30: 16 | E30: Amarre | G30: 3 | I30: 6 | N30: 3 | O30: 4 | T30: 45270 | U30: X | V30: 4 | Y30: 45270 | Z30: X | AA30: 12
B31: U.P. PESADO | C31: PINOS 2 | D31: 17 | E31: Pase | G31: 3 | O31: 3 | P31: 3 | T31: 45270 | U31: X | V31: 6 | W31: NIVEL 2: DELTA FASE "B" LADO DE SM | Y31: 45270 | Z31: X | AA31: 6
B32: U.P. PESADO | C32: PINOS 2 | D32: 18 | E32: Amarre | G32: 3 | I32: 6 | N32: 3 | O32: 3 | U32: X | V32: 3 | Y32: 45270 | Z32: X | AA32: 12
B33: U.P. PESADO | C33: PINOS 2 | D33: 19 | E33: Pase | G33: 3 | Y33: 45270 | Z33: X | AA33: 3
B34: U.P. PESADO | C34: PINOS 2 | D34: 20 | E34: Amarre a 90º | G34: 2 | I34: 6 | N34: 3 | O34: 3 | T34: 45270 | U34: X | V34: 3 | Y34: 45270 | Z34: X | AA34: 11
B35: U.P. PESADO | C35: PINOS 2 | D35: 21 | E35: Pase | G35: 3 | Y35: 45270 | Z35: X | AA35: 3
B36: U.P. PESADO | C36: PINOS 2 | D36: 22 | E36: Pase | G36: 3 | N36: 3 | Y36: 45270 | Z36: X | AA36: 6
B37: U.P. PESADO | C37: PINOS 2 | D37: 23 | E37: Pase | G37: 3 | Y37: 45270 | Z37: X | AA37: 3 | AB37: NIVEL 3: FASE "C" CON ALTOS DECIBELES | AD37: 45337 | AE37: Ejecutada
B38: U.P. PESADO | C38: PINOS 2 | D38: 24 | E38: Amarre a 45º | G38: 2 | I38: 6 | N38: 3 | O38: 3 | T38: 45270 | U38: X | V38: 3 | Y38: 45270 | Z38: X | AA38: 11
B39: U.P. PESADO | C39: PINOS 2 | D39: 25 | E39: Pase | G39: 3 | Y39: 45270 | Z39: X | AA39: 3
B40: U.P. PESADO | C40: PINOS 2 | D40: 26 | E40: Amarre a 90º | G40: 2 | I40: 6 | N40: 3 | O40: 3 | T40: 45270 | U40: X | V40: 3 | Y40: 45270 | Z40: X | AA40: 11
B41: U.P. PESADO | C41: PINOS 2 | D41: 27 | E41: Pase con deriv a 45º | G41: 5 | H41: 3 | O41: 3 | P41: 3 | T41: 45270 | U41: X | V41: 6 | Y41: 45270 | Z41: X | AA41: 8
B42: U.P. PESADO | C42: PINOS 2 | D42: 28 | E42: Pase | G42: 3 | N42: 3 | Y42: 45270 | Z42: X | AA42: 6
B43: U.P. PESADO | C43: PINOS 2 | D43: 29 | E43: Pase | G43: 3 | Y43: 45270 | Z43: X | AA43: 3
B44: U.P. PESADO | C44: PINOS 2 | D44: 30 | E44: Amarre a 90º | I44: 6 | N44: 3 | O44: 2 | P44: 3 | T44: 45270 | U44: X | V44: 11 | Y44: 45270 | Z44: X | AA44: 15
B45: U.P. PESADO | C45: PINOS 2 | D45: 31 | E45: Pase | G45: 3 | Y45: 45270 | Z45: X | AA45: 3
...

Sheet Pinos 3
E3: Calidad | AF3: CODIGO: FO-CA-GE-02-E
AF4: REVISION: 00
E5: Máster de Inspección | AF5: FECHA DE EMISIÓN: 28-02-2024
B8: Nombre del Proyecto: | E8: "Mantenimiento En El Sistema Eléctrico De Distribución 13.8 Kv De La División Ayacucho" | Y8: Nro. de Contrato: | AB8: 4600135303
B9: Disciplina | E9: Electricidad | Y9: Ubicación: | AB9: División Ayacucho
B10: DATOS | F10: MANTENIMIENTO PREDICTIVO EJECUTADO | AD10: MANTENIMIENTO PREVENTIVO EJECUTADO
F12: VISUAL | T12: TERMOGRAFÍA | Y12: ULTRASONIDO | AD12: INTERVENCIÓN
F13: Componentes
B14: Frente | C14: Circuito | D14: Nro. De poste | E14: Descripción | F14: Fecha V | G14: Aislador de Espiga (AE) | H14: Aislador Polimericos (APT ) 34,5 Kv | I14: Aislador de Cadena (Ac) | J14: Aislador Polimericos (APs ) 69 Kv | K14: Cortacorriente (CC) | L14: Abierto | M14: Cerrado | N14: Pararrayos (P) | O14: Grapa ( G ) | P14: Seccionador (SM) | Q14: Abierto 2 | R14: Cerrado3 | S14: Falla Detectada V | T14: Fecha T | U14: Ejecutado T | V14: Puntos de Termografía | W14: Falla Detectada T | X14: Observación T | Y14: Fecha UT | Z14: Ejecutado UT | AA14: Puntos de Ultrasonido | AB14: Falla Detectada UT | AC14: Observación UT | AD14: Fecha | AE14: Ejecutado MTTO | AF14: Observación
B15: U.P. PESADO | C15: PINOS 3 | D15: 1 | E15: Amarre Terminal | J15: 3 | O15: 3 | P15: 3 | T15: 45268 | U15: X | V15: 12 | W15: DELTA FASE "A-B-C" | Y15: 45268 | Z15: X | AA15: 9 | AB15: FASE A EFECTO CORONA | AD15: 45376 | AE15: Ejecutada
B16: U.P. PESADO | C16: PINOS 3 | D16: 2 | E16: Pase | G16: 3 | Y16: 45268 | Z16: X | AA16: 3
B17: U.P. PESADO | C17: PINOS 3 | D17: 3 | E17: Pase con deriv a 90º (Interconexion de Pinos 3 con Merey 29 | G17: 5 | O17: 4 | P17: 3 | S17: SM Fase A dañado | T17: 45268 | U17: X | V17: 7 | Y17: 45268 | Z17: X | AA17: 10 | AE17: Ejecutada | AF17: Esta OK, Fue inspeccionada
B18: U.P. PESADO | C18: PINOS 3 | D18: 4 | E18: Amarre a 90º | H18: 3 | I18: 3 | O18: 7 | P18: 3 | T18: 45268 | U18: X | V18: 16 | W18: DELTA EN SM, FASE A Y B | Y18: 45268 | Z18: X | AA18: 12 | AB18: ALTO DECIBELES EN FASE A Y B | AD18: 45275 | AE18: Ejecutada
B19: U.P. PESADO | C19: PINOS 3 | D19: 5 | E19: Amarre | G19: 1 | I19: 6 | O19: 6 | T19: 45268 | U19: X | V19: 6 | Y19: 45268 | Z19: X | AA19: 7
B20: U.P. PESADO | C20: PINOS 3 | D20: 6 | E20: Pase | G20: 3 | Y20: 45268 | Z20: X | AA20: 3 | AB20: PRESENTE ALTO NIVELES DE DECIBELES | AD20: 45300 | AE20: Ejecutada
B21: U.P. PESADO | C21: PINOS 3 | D21: 7 | E21: Pase | G21: 3 | Y21: 45268 | Z21: X | AA21: 3 | AB21: PRESENTE ALTO NIVELES DE DECIBELES, Y FISURA | AD21: 44935 | AE21: Ejecutada
B22: U.P. PESADO | C22: PINOS 3 | D22: 8 | E22: Pase | G22: 3 | Y22: 45268 | Z22: X | AA22: 3
B23: U.P. PESADO | C23: PINOS 3 | D23: 9 | E23: Pase | G23: 3 | S23: Espiga Fase A presenta fogonazo | Y23: 45268 | Z23: X | AA23: 3
B24: U.P. PESADO | C24: PINOS 3 | D24: 10 | E24: Pase | G24: 3 | Y24: 45268 | Z24: X | AA24: 3
B25: U.P. PESADO | C25: PINOS 3 | D25: 11 | E25: Pase | G25: 3 | Y25: 45268 | Z25: X | AA25: 3
B26: U.P. PESADO | C26: PINOS 3 | D26: 12 | E26: Pase con deriv a 45º | G26: 3 | H26: 3 | O26: 3 | P26: 3 | U26: X | V26: 6 | Y26: 45268 | Z26: X | AA26: 12 | AB26: ALTO DECIBELES EN FASE A Y B | AD26: 45302 | AE26: Ejecutada
B27: U.P. PESADO | C27: PINOS 3 | D27: 13 | E27: Pase con deriv a 90º | G27: 4 | I27: 3 | O27: 6 | P27: 3 | T27: 45268 | U27: X | V27: 15 | Y27: 45268 | Z27: X | AA27: 13 | AB27: ALTO DECIBELES EN FASE B | AD27: 45302 | AE27: Ejecutada
B28: U.P. PESADO | C28: PINOS 3 | D28: 14 | E28: Amarre | I28: 6 | O28: 6 | P28: 3 | T28: 45268 | U28: X | V28: 15 | W28: DELTA FASE "B" EN GRAPA | Y28: 45268 | Z28: X | AA28: 12 | AB28: ALTO DECIBELES EN FASE B Y C
B29: U.P. PESADO | C29: PINOS 3 | D29: 15 | E29: Amarre Con deriv a 90º | G29: 2 | H29: 3 | I29: 6 | K29: 3 | N29: 3 | O29: 6 | T29: 45268 | U29: X | V29: 9 | Y29: 45268 | Z29: X | AA29: 17 | AB29: PARARRAYOS Y CC CON ALTO DECIBELES
B30: U.P. PESADO | C30: PINOS 3 | D30: 16 | E30: Amarre | G30: 2 | I30: 6 | O30: 5 | P30: 2 | T30: 45268 | U30: X | V30: 11 | W30: DELTA EN SM | Y30: 45268 | Z30: X | AA30: 12 | AB30: FASE B Y C ALTOS DECIBELES | AD30: 45370 | AE30: Ejecutada
B31: U.P. PESADO | C31: PINOS 3 | D31: 17 | E31: Amarre con deriv a 45° | H31: 3 | I31: 6 | O31: 8 | T31: 45268 | U31: X | V31: 8 | Y31: 45268 | Z31: X | AA31: 9
B32: U.P. PESADO | C32: PINOS 3 | D32: 18 | E32: Pase | G32: 3 | K32: 3 | N32: 3 | O32: 3 | T32: 45268 | U32: X | V32: 12 | Y32: 45268 | Z32: X | AA32: 9 | AB32: Alto decibel en Pararrayos y Cortacorriente | AD32: 45303 | AE32: Ejecutada
B33: U.P. PESADO | C33: PINOS 3 | D33: 19 | E33: Amarre Terminal | I33: 3 | K33: 3 | N33: 3 | S33: CC fase A dañado | U33: X | V33: 3 | Y33: 45268 | Z33: X | AA33: 9 | AB33: Alto decibel en Pararrayos | AD33: 45303 | AE33: Ejecutada
B34: U.P. PESADO | C34: PINOS 3 | D34: 20 | E34: Amarre a 90º | G34: 2 | I34: 6 | N34: 3 | O34: 3 | T34: 45268 | U34: X | V34: 3 | W34: DELTA FASE "B" | Y34: 45268 | Z34: X | AA34: 11
B35: U.P. PESADO | C35: PINOS 3 | D35: 21 | E35: Amarre | I35: 3 | P35: 3 | Y35: 45268 | Z35: X | AA35: 6
B36: U.P. PESADO | C36: PINOS 3 | D36: 22 | E36: Amarre a 90º | G36: 2 | I36: 6 | O36: 3 | S36: Aisladores dañados | T36: 45268 | U36: X | V36: 3 | Y36: 45268 | Z36: X | AA36: 8 | AB36: Espigas Fase A con alto decibel | AD36: 45269 | AE36: Ejecutada
B37: U.P. PESADO | C37: PINOS 3 | D37: 23 | E37: Pase | G37: 3 | Y37: 45268 | Z37: X | AA37: 3
B38: U.P. PESADO | C38: PINOS 3 | D38: 24 | E38: Amarre 45º | G38: 4 | I38: 3 | K38: 3 | N38: 3 | P38: 3 | Y38: 45268 | Z38: X | AA38: 16 | AB38: Seccionador Fase B y C con alto decibel | AD38: 45371 | AE38: Ejecutada
B39: U.P. PESADO | C39: PINOS 3 | D39: 25 | E39: Pase con deriv a 90º | G39: 3 | H39: 3 | O39: 3 | T39: 45268 | U39: X | V39: 3 | Y39: 45268 | Z39: X | AA39: 6
B40: U.P. PESADO | C40: PINOS 3 | D40: 26 | E40: Amarre | H40: 3 | I40: 3 | P40: 3 | T40: 45268 | U40: X | V40: 9 | Y40: 45268 | Z40: X | AA40: 12
B41: U.P. PESADO | C41: PINOS 3 | D41: 27 | E41: Amarre a 90º | G41: 2 | I41: 6 | O41: 6 | T41: 45268 | U41: X | V41: 6 | W41: DELTA FASE "A" | Y41: 45268 | Z41: X | AA41: 8
B42: U.P. PESADO | C42: PINOS 3 | D42: 28 | E42: Terminal | H42: 3 | Y42: 45268 | Z42: X | AA42: 3
B43: U.P. PESADO | C43: PINOS 3 | D43: 29 | E43: Suspension | I43: 3 | Y43: 45268 | Z43: X | AA43: 3
B44: U.P. PESADO | C44: PINOS 3 | D44: 30 | E44: Suspension | I44: 3 | Y44: 45268 | Z44: X | AA44: 3
B45: U.P. PESADO | C45: PINOS 3 | D45: 31 | E45: Suspension | I45: 3 | Y45: 45268 | Z45: X | AA45: 3
...

Sheet Rio Claro
E3: Calidad | AF3: CODIGO: FO-CA-GE-02-E
AF4: REVISION: 00
E5: Máster de Inspección | AF5: FECHA DE EMISIÓN: 28-02-2024
B8: Nombre del Proyecto: | E8: "Mantenimiento En El Sistema Eléctrico De Distribución 13.8 Kv De La División Ayacucho" | Y8: Nro. de Contrato: | AB8: 4600135303
B9: Disciplina | E9: Electricidad | Y9: Ubicación: | AB9: División Ayacucho
B10: DATOS | F10: MANTENIMIENTO PREDICTIVO EJECUTADO | AD10: MANTENIMIENTO PREVENTIVO EJECUTADO
F12: VISUAL | T12: TERMOGRAFÍA | Y12: ULTRASONIDO | AD12: INTERVENCIÓN
F13: Componentes
B14: Frente | C14: Circuito | D14: Nro. De poste | E14: Descripción | F14: Fecha V | G14: Aislador de Espiga (AE) | H14: Aislador Polimericos (APT ) 34,5 Kv | I14: Aislador de Cadena (Ac) | J14: Aislador Polimericos (APs ) 69 Kv | K14: Cortacorriente (CC) | L14: Abierto | M14: Cerrado | N14: Pararrayos (P) | O14: Grapa ( G ) | P14: Seccionador (SM) | Q14: Abierto 2 | R14: Cerrado3 | S14: Falla Detectada V | T14: Fecha T | U14: Ejecutado T | V14: Puntos de Termografía | W14: Falla Detectada T | X14: Observación T | Y14: Fecha UT | Z14: Ejecutado UT | AA14: Puntos de Ultrasonido | AB14: Falla Detectada UT | AC14: Observación UT | AD14: Fecha | AE14: Ejecutado MTTO | AF14: Observación
B15: U.P. PESADO | C15: Rio Claro | D15: 5 | E15: Pase con derivacion en 90° | G15: 5 | H15: 3 | O15: 8 | S15: NIVEL 2: FALTAN LOS 3 PARARRAYOS | T15: 45322 | U15: X | V15: 8 | Y15: 45415 | Z15: X | AA15: 8
B16: U.P. PESADO | C16: Rio Claro | D16: 6 | E16: Pase con derivacion en 90° | G16: 3 | I16: 3 | N16: 3 | O16: 6 | S16: NIVEL 2: BAJANTE DE PARARRAYOS CORTADOS | T16: 45322 | U16: X | V16: 6 | Y16: 45415 | Z16: X | AA16: 9
B17: U.P. PESADO | C17: Rio Claro | D17: 7 | E17: Pase | G17: 3 | Y17: 45415 | Z17: X | AA17: 3
B18: U.P. PESADO | C18: Rio Claro | D18: 8 | E18: Pase | G18: 3 | N18: 3 | Y18: 45415 | Z18: X | AA18: 6
B19: U.P. PESADO | C19: Rio Claro | D19: 9 | E19: Pase | G19: 3 | Y19: 45415 | Z19: X | AA19: 3
B20: U.P. PESADO | C20: Rio Claro | D20: 10 | E20: Pase | G20: 3 | Y20: 45415 | Z20: X | AA20: 3
B21: U.P. PESADO | C21: Rio Claro | D21: 11 | E21: Pase | G21: 3 | N21: 3 | Y21: 45415 | Z21: X | AA21: 6
B22: U.P. PESADO | C22: Rio Claro | D22: 12 | E22: Pase | G22: 3 | Y22: 45415 | Z22: X | AA22: 3
B23: U.P. PESADO | C23: Rio Claro | D23: 13 | E23: Pase | G23: 3 | S23: NIVEL 2: AUSENCIA DE PARARRAYOS Y BAJANTE DE PAT CORTADOS | Y23: 45415 | Z23: X | AA23: 3
B24: U.P. PESADO | C24: Rio Claro | D24: 14 | E24: Pase | G24: 3 | N24: 3 | S24: NIVEL 2: ESPIGA FASE B ESTA INCLINADA | Y24: 45415 | Z24: X | AA24: 6
B25: U.P. PESADO | C25: Rio Claro | D25: 15 | E25: Pase | G25: 3 | S25: NIVEL 2: BAJANTE DE PAT DE CABLE GUARDA CORTADO | Y25: 45415 | Z25: X | AA25: 3
B26: U.P. PESADO | C26: Rio Claro | D26: 16 | E26: Pase | G26: 3 | S26: NIVEL 2: FALTAN 3 PARARRAYOS | Y26: 45415 | Z26: X | AA26: 3
B27: U.P. PESADO | C27: Rio Claro | D27: 17 | E27: Pase | G27: 3 | N27: 3 | Y27: 45415 | Z27: X | AA27: 6
B28: U.P. PESADO | C28: Rio Claro | D28: 18 | E28: Amarre en 90° | G28: 5 | H28: 6 | K28: 3 | N28: 3 | O28: 8 | T28: 45322 | U28: X | V28: 11 | Y28: 45415 | Z28: X | AA28: 17
B29: U.P. PESADO | C29: Rio Claro | D29: 19 | E29: Amarre | H29: 6 | N29: 3 | O29: 6 | T29: 45322 | U29: X | V29: 6 | Y29: 45415 | Z29: X | AA29: 9
B30: U.P. PESADO | C30: Rio Claro | D30: 20 | E30: Pase | G30: 3 | Y30: 45415 | Z30: X | AA30: 3
B31: U.P. PESADO | C31: Rio Claro | D31: 21 | E31: Pase | G31: 3 | Y31: 45415 | Z31: X | AA31: 3
B32: U.P. PESADO | C32: Rio Claro | D32: 22 | E32: Pase | G32: 3 | N32: 3 | S32: NIVEL 2: PAT DE PARARRAYOS COLOCADOS EN CABLE DE GUARDA | Y32: 45415 | Z32: X | AA32: 6
B33: U.P. PESADO | C33: Rio Claro | D33: 23 | E33: Pase con derivacion en 90° | G33: 4 | I33: 3 | O33: 6 | P33: 3 | T33: 45322 | U33: X | V33: 15 | Y33: 45415 | Z33: X | AA33: 13
B34: U.P. PESADO | C34: Rio Claro | D34: 24 | E34: Pase | G34: 3 | N34: 3 | Y34: 45415 | Z34: X | AA34: 6
B35: U.P. PESADO | C35: Rio Claro | D35: 25 | E35: Amarre en 45° | G35: 1 | I35: 6 | O35: 6 | T35: 45322 | U35: X | V35: 6 | Y35: 45415 | Z35: X | AA35: 7
B36: U.P. PESADO | C36: Rio Claro | D36: 26 | E36: Pase | G36: 3 | K36: 3 | O36: 3 | T36: 45322 | U36: X | V36: 6 | Y36: 45415 | Z36: X | AA36: 6
B37: U.P. PESADO | C37: Rio Claro | D37: 27 | E37: Poste terminal | I37: 3 | K37: 3 | O37: 3 | T37: 45322 | U37: X | V37: 6 | Y37: 45415 | Z37: X | AA37: 6
B38: U.P. PESADO | C38: Rio Claro | D38: 28 | E38: Pase | G38: 3 | Y38: 45415 | Z38: X | AA38: 3
B39: U.P. PESADO | C39: Rio Claro | D39: 29 | E39: Amarre en 90° | G39: 2 | I39: 6 | N39: 3 | O39: 4 | T39: 45322 | U39: X | V39: 4 | Y39: 45415 | Z39: X | AA39: 11
B40: U.P. PESADO | C40: Rio Claro | D40: 30 | E40: Pase | G40: 3 | Y40: 45415 | Z40: X | AA40: 3
B41: U.P. PESADO | C41: Rio Claro | D41: 31 | E41: Amarre en 90° | G41: 1 | H41: 3 | I41: 3 | N41: 3 | O41: 3 | T41: 45322 | U41: X | V41: 3 | Y41: 45415 | Z41: X | AA41: 10
B42: U.P. PESADO | C42: Rio Claro | D42: 32 | E42: Pase | G42: 3 | S42: NIVEL 3: AE DE ESPIGA DESPRENDIDO EN FASE B | Y42: 45415 | Z42: X | AA42: 3 | AD42: 45422 | AE42: Ejecutada
B43: U.P. PESADO | C43: Rio Claro | D43: 33 | E43: Pase | G43: 3 | S43: NIVEL 2: FALTAN 3 PARARRAYOS | Y43: 45415 | Z43: X | AA43: 3
B44: U.P. PESADO | C44: Rio Claro | D44: 34 | E44: Pase | G44: 3 | Y44: 45415 | Z44: X | AA44: 3
B45: U.P. PESADO | C45: Rio Claro | D45: 35 | E45: Pase | G45: 3 | S45: NIVEL 2: FALTAN 3 PARARRAYOS | Y45: 45415 | Z45: X | AA45: 3
...

Sheet Merey-29
E3: Calidad | AF3: CODIGO: FO-CA-GE-02-E
AF4: REVISION: 00
E5: Máster de Inspección | AF5: FECHA DE EMISIÓN: 28-02-2024
B8: Nombre del Proyecto: | E8: "Mantenimiento En El Sistema Eléctrico De Distribución 13.8 Kv De La División Ayacucho" | Y8: Nro. de Contrato: | AB8: 4600135303
B9: Disciplina | E9: Electricidad | Y9: Ubicación: | AB9: División Ayacucho
B10: DATOS | F10: MANTENIMIENTO PREDICTIVO EJECUTADO | AD10: MANTENIMIENTO PREVENTIVO EJECUTADO
F12: VISUAL | T12: TERMOGRAFÍA | Y12: ULTRASONIDO | AD12: INTERVENCIÓN
F13: Componentes
B14: Frente | C14: Circuito | D14: Nro. De poste | E14: Descripción | F14: Fecha V | G14: Aislador de Espiga (AE) | H14: Aislador Polimericos (APT ) 34,5 Kv | I14: Aislador de Cadena (Ac) | J14: Aislador Polimericos (APs ) 69 Kv | K14: Cortacorriente (CC) | L14: Abierto | M14: Cerrado | N14: Pararrayos (P) | O14: Grapa ( G ) | P14: Seccionador (SM) | Q14: Abierto 2 | R14: Cerrado3 | S14: Falla Detectada V | T14: Fecha T | U14: Ejecutado T | V14: Puntos de Termografía | W14: Falla Detectada T | X14: Observación T | Y14: Fecha UT | Z14: Ejecutado UT | AA14: Puntos de Ultrasonido | AB14: Falla Detectada UT | AC14: Observación UT | AD14: Fecha | AE14: Ejecutado MTTO | AF14: Observación
B15: U.P. PESADO | C15: MEREY 29 | D15: 1 | E15: Poste Terminal | G15: 4 | H15: 6 | N15: 6 | P15: 3 | R15: X | T15: 45322 | U15: X | V15: 9 | Y15: 45333 | Z15: X | AA15: 12 | AD15: 45420 | AE15: Ejecutada
B16: U.P. PESADO | C16: MEREY 29 | D16: 2 | E16: Suspensión | I16: 6 | S16: NIVEL 3: Reemplazar mordazas y Cadenas de amarre; Terna desprendida | Y16: 45333 | Z16: X | AA16: 3 | AD16: 45421 | AE16: Ejecutada
B17: U.P. PESADO | C17: MEREY 29 | D17: 3 | E17: Suspensión | I17: 6 | S17: NIVEL 3: Reemplazar mordazas y Cadenas de amarre; Terna desprendida | Y17: 45333 | Z17: X | AA17: 3 | AD17: 45421 | AE17: Ejecutada
B18: U.P. PESADO | C18: MEREY 29 | D18: 4 | E18: Suspensión | I18: 6 | S18: NIVEL 3: Reemplazar mordazas y Cadenas de amarre; Terna desprendida | Y18: 45333 | Z18: X | AA18: 3 | AD18: 45421 | AE18: Ejecutada
B19: U.P. PESADO | C19: MEREY 29 | D19: 5 | E19: Amarre en 45° | G19: 3 | H19: 6 | I19: 6 | O19: 3 | T19: 45322 | U19: X | V19: 3 | Y19: 45333 | Z19: X | AA19: 9 | AD19: 45420 | AE19: Ejecutada
B20: U.P. PESADO | C20: MEREY 29 | D20: 6 | E20: Suspensión | I20: 5 | S20: NIVEL 3: Reemplazar mordazas y Cadenas de amarre; Terna desprendida | Y20: 45333 | Z20: X | AA20: 3 | AD20: 45421 | AE20: Ejecutada
B21: U.P. PESADO | C21: MEREY 29 | D21: 7 | E21: Suspensión | I21: 3 | S21: NIVEL 3: Reemplazar mordazas y Cadenas de amarre; Terna desprendida | Y21: 45333 | Z21: X | AA21: 3 | AD21: 45405 | AE21: Ejecutada
B22: U.P. PESADO | C22: MEREY 29 | D22: 8 | E22: Amarre | H22: 12 | O22: 3 | T22: 45322 | U22: X | V22: 3 | Y22: 45333 | Z22: X | AA22: 6 | AD22: 45418 | AE22: Ejecutada
B23: U.P. PESADO | C23: MEREY 29 | D23: 9 | E23: Suspensión | I23: 6 | S23: NIVEL 3: Reemplazar mordazas y Cadenas de amarre; Terna desprendida | Y23: 45333 | Z23: X | AA23: 3 | AD23: 45406 | AE23: Ejecutada
B24: U.P. PESADO | C24: MEREY 29 | D24: 10 | E24: Suspensión | I24: 6 | S24: NIVEL 3: Aislador de la Fase A dañado | Y24: 45333 | Z24: X | AA24: 3 | AD24: 45396 | AE24: Ejecutada
B25: U.P. PESADO | C25: MEREY 29 | D25: 11 | E25: Suspensión | I25: 6 | S25: NIVEL 3: Reemplazar mordazas y Cadenas de amarre; Terna desprendida | Y25: 45333 | Z25: X | AA25: 3 | AD25: 45406 | AE25: Ejecutada
B26: U.P. PESADO | C26: MEREY 29 | D26: 12 | E26: Suspensión | I26: 6 | S26: NIVEL 3: Reemplazar mordazas y Cadenas de amarre; Terna desprendida | Y26: 45333 | Z26: X | AA26: 3 | AD26: 45396 | AE26: Ejecutada
B27: U.P. PESADO | C27: MEREY 29 | D27: 13 | E27: Suspensión | I27: 6 | S27: NIVEL 3: Reemplazar mordazas y Cadenas de amarre; Aislador de cadena dañado | Y27: 45333 | Z27: X | AA27: 3 | AD27: 45406 | AE27: Ejecutada
B28: U.P. PESADO | C28: MEREY 29 | D28: 14 | E28: Amarre | H28: 6 | I28: 6 | O28: 3 | T28: 45322 | U28: X | V28: 3 | Y28: 45333 | Z28: X | AA28: 6 | AD28: 45416 | AE28: Ejecutada
B29: U.P. PESADO | C29: MEREY 29 | D29: 15 | E29: Amarre | H29: 6 | I29: 6 | O29: 3 | T29: 45322 | U29: X | V29: 3 | Y29: 45333 | Z29: X | AA29: 6
B30: U.P. PESADO | C30: MEREY 29 | D30: 16 | E30: Suspensión | I30: 6 | S30: NIVEL 3: Reemplazar Cadenas de amarre; Aislador de cadena dañado | Y30: 45333 | Z30: X | AA30: 3 | AD30: 45406 | AE30: Ejecutada
B31: U.P. PESADO | C31: MEREY 29 | D31: 17 | E31: Suspensión | I31: 6 | S31: NIVEL 3: Reemplazar Cadenas de amarre | Y31: 45333 | Z31: X | AA31: 3 | AD31: 45407 | AE31: Ejecutada
B32: U.P. PESADO | C32: MEREY 29 | D32: 18 | E32: Suspensión | I32: 6 | S32: NIVEL 3: Reemplazar mordazas y Cadenas de amarre; Aislador de cadena dañado | Y32: 45333 | Z32: X | AA32: 3 | AB32: NIVEL 3: Presenta altos decibeles, Fase A,B,C | AC32: Cadena Rota | AD32: 45395 | AE32: Ejecutada
B33: U.P. PESADO | C33: MEREY 29 | D33: 19 | E33: Suspensión | I33: 6 | S33: NIVEL 3: Reemplazar mordazas y Cadenas de amarre | Y33: 45333 | Z33: X | AA33: 3 | AD33: 45407 | AE33: Ejecutada
B34: U.P. PESADO | C34: MEREY 29 | D34: 20 | E34: Amarre | H34: 6 | I34: 6 | O34: 3 | T34: 45322 | U34: X | V34: 3 | Y34: 45333 | Z34: X | AA34: 6 | AD34: 45418 | AE34: Ejecutada
B35: U.P. PESADO | C35: MEREY 29 | D35: 21 | E35: Amarre | H35: 6 | I35: 6 | O35: 3 | S35: NIVEL 2: Instalar Pararrayos | T35: 45325 | U35: X | V35: 3 | Y35: 45333 | Z35: X | AA35: 6 | AD35: 45418 | AE35: Ejecutada
B36: U.P. PESADO | C36: MEREY 29 | D36: 22 | E36: Suspensión | I36: 6 | S36: Pines de acople de los aisladores presentan corrosion | Y36: 45333 | Z36: X | AA36: 3 | AD36: 45407 | AE36: Ejecutada
B37: U.P. PESADO | C37: MEREY 29 | D37: 23 | E37: Suspensión | I37: 6 | S37: Pines de acople de los aisladores presentan corrosion | Y37: 45333 | Z37: X | AA37: 3 | AD37: 45407 | AE37: Ejecutada
B38: U.P. PESADO | C38: MEREY 29 | D38: 24 | E38: Suspensión | I38: 6 | S38: Pines de acople de los aisladores presentan corrosion | Y38: 45333 | Z38: X | AA38: 3 | AD38: 45414 | AE38: Ejecutada
B39: U.P. PESADO | C39: MEREY 29 | D39: 25 | E39: Suspensión | I39: 6 | S39: NIVEL 3: Reemplazar mordazas y Cadenas de amarre | Y39: 45333 | Z39: X | AA39: 3 | AD39: 45414 | AE39: Ejecutada
B40: U.P. PESADO | C40: MEREY 29 | D40: 26 | E40: Amarre | H40: 12 | O40: 3 | S40: NIVEL 3: Reemplazar Cadenas de amarre | T40: 45325 | U40: X | V40: 3 | Y40: 45333 | Z40: X | AA40: 6 | AD40: 45418 | AE40: Ejecutada
B41: U.P. PESADO | C41: MEREY 29 | D41: 27 | E41: Suspensión | I41: 6 | S41: NIVEL 3: Reemplazar Cadenas de amarre | Y41: 45333 | Z41: X | AA41: 3 | AD41: 45414 | AE41: Ejecutada
B42: U.P. PESADO | C42: MEREY 29 | D42: 28 | E42: Suspensión | I42: 6 | S42: NIVEL 3: Reemplazar Cadenas de amarre | Y42: 45333 | Z42: X | AA42: 3 | AD42: 45414 | AE42: Ejecutada
B43: U.P. PESADO | C43: MEREY 29 | D43: 29 | E43: Suspensión | I43: 6 | S43: Pines de acople de los aisladores presentan corrosion | Y43: 45333 | Z43: X | AA43: 3 | AD43: 45414 | AE43: Ejecutada
B44: U.P. PESADO | C44: MEREY 29 | D44: 30 | E44: Suspensión | I44: 6 | S44: Pines de acople de los aisladores presentan corrosion | Y44: 45333 | Z44: X | AA44: 3 | AD44: 45414 | AE44: Ejecutada
B45: U.P. PESADO | C45: MEREY 29 | D45: 31 | E45: Suspensión | I45: 6 | S45: NIVEL 3: Reemplazar Cadenas de amarre | Y45: 45333 | Z45: X | AA45: 3 | AD45: 45414 | AE45: Ejecutada
...

Sheet Merey-20
E3: Calidad | AF3: CODIGO: FO-CA-GE-02-E
AF4: REVISION: 00
E5: Máster de Inspección | AF5: FECHA DE EMISIÓN: 28-02-2024
B8: Nombre del Proyecto: | E8: "Mantenimiento En El Sistema Eléctrico De Distribución 13.8 Kv De La División Ayacucho" | Y8: Nro. de Contrato: | AB8: 4600135303
B9: Disciplina | E9: Electricidad | Y9: Ubicación: | AB9: División Ayacucho
B10: DATOS | F10: MANTENIMIENTO PREDICTIVO EJECUTADO | AD10: MANTENIMIENTO PREVENTIVO EJECUTADO
F12: VISUAL | T12: TERMOGRAFÍA | Y12: ULTRASONIDO | AD12: INTERVENCIÓN
F13: Componentes
B14: Frente | C14: Circuito | D14: Nro. De poste | E14: Descripción | F14: Fecha V | G14: Aislador de Espiga (AE) | H14: Aislador Polimericos (APT ) 34,5 Kv | I14: Aislador de Cadena (Ac) | J14: Aislador Polimericos (APs ) 69 Kv | K14: Cortacorriente (CC) | L14: Abierto | M14: Cerrado | N14: Pararrayos (P) | O14: Grapa ( G ) | P14: Seccionador (SM) | Q14: Abierto 2 | R14: Cerrado3 | S14: Falla Detectada V | T14: Fecha T | U14: Ejecutado T | V14: Puntos de Termografía | W14: Falla Detectada T | X14: Observación T | Y14: Fecha UT | Z14: Ejecutado UT | AA14: Puntos de Ultrasonido | AB14: Falla Detectada UT | AC14: Observación UT | AD14: Fecha | AE14: Ejecutado MTTO | AF14: Observación
B15: U.P. PESADO | C15: MEREY-20 | D15: 1 | E15: Poste Terminal | G15: 6 | H15: 6 | N15: 6 | O15: 4 | P15: 6 | S15: Contaminación. No se aprecia la conexión de PAT de los pararrayos. 6 seccionadores, 3 abiertos y 3 cerrados. La tornillería de los terminales de los seccionadores que estan cerrrados presentan corrosión, se recomienda cambiarlos. En el vano comprendido entre los postes 1 y 2, hay dos emplames en la fase C con conectores automaticos. | T15: 45364 | U15: X | V15: 16 | X15: 3 SM Abierto y 3 Cerrado | Y15: 45390 | Z15: X | AA15: 20
B16: U.P. PESADO | C16: MEREY-20 | D16: 2 | E16: Poste suspensión | I16: 6 | N16: 6 | S16: Aisladores y pararrayos muy contaminados. PAT de los pararrayos conectado directo a poste. | Y16: 45390 | Z16: X | AA16: 12
B17: U.P. PESADO | C17: MEREY-20 | D17: 3 | E17: Poste suspensión | I17: 6 | S17: Contaminación | Y17: 45390 | Z17: X | AA17: 6
B18: U.P. PESADO | C18: MEREY-20 | D18: 4 | E18: Poste suspensión | I18: 6 | S18: Contaminación. Pin de acople de los aisladores a la grapa de suspensión de la línea presenta corrosión. | Y18: 45390 | Z18: X | AA18: 6
B19: U.P. PESADO | C19: MEREY-20 | D19: 5 | E19: Amarre | I19: 12 | N19: 6 | O19: 12 | S19: Aisladores y pararrayos muy contaminados. | T19: 45364 | U19: X | V19: 12 | Y19: 45390 | Z19: X | AA19: 18
B20: U.P. PESADO | C20: MEREY-20 | D20: 6 | E20: Amarre en 45° | I20: 12 | O20: 12 | S20: Aisladores muy contaminados. | T20: 45364 | U20: X | V20: 12 | Y20: 45390 | Z20: X | AA20: 12
B21: U.P. PESADO | C21: MEREY-20 | D21: 7 | E21: Poste suspensión | I21: 6 | S21: NIVEL 3: 3 cadenas de aisladores dañados, de los cuales una tiene un aislador partido. Se deben reemplazar. | Y21: 45390 | Z21: X | AA21: 6
B22: U.P. PESADO | C22: MEREY-20 | D22: 8 | E22: Poste suspensión | I22: 6 | N22: 6 | S22: Contaminación. Pararrayos muy contaminados. PAT de los pararrayos conectado directo a poste. | Y22: 45390 | Z22: X | AA22: 12 | AB22: NIVEL 3: EFECTO CORONA EN P FASE B Y C, (LADO IZQUIERDO); AC EFECTO CORONA EN FASE A, B Y C
B23: U.P. PESADO | C23: MEREY-20 | D23: 9 | E23: Amarre | I23: 12 | O23: 24 | S23: Contaminación | T23: 45364 | U23: X | V23: 24 | W23: Delta en grapa fase A | Y23: 45390 | Z23: X | AA23: 12
B24: U.P. PESADO | C24: MEREY-20 | D24: 10 | E24: Poste suspensión | I24: 6 | S24: Contaminación | Y24: 45390 | Z24: X | AA24: 6
B25: U.P. PESADO | C25: MEREY-20 | D25: 11 | E25: Poste suspensión | I25: 6 | N25: 6 | S25: Contaminación | Y25: 45390 | Z25: X | AA25: 12
B26: U.P. PESADO | C26: MEREY-20 | D26: 12 | E26: Poste suspensión | I26: 6 | S26: Contaminación | Y26: 45390 | Z26: X | AA26: 6
B27: U.P. PESADO | C27: MEREY-20 | D27: 13 | E27: Poste suspensión | I27: 6 | S27: Contaminación | Y27: 45390 | Z27: X | AA27: 6
B28: U.P. PESADO | C28: MEREY-20 | D28: 14 | E28: Poste suspensión | I28: 6 | N28: 6 | S28: Contaminación | Y28: 45390 | Z28: X | AA28: 12
B29: U.P. PESADO | C29: MEREY-20 | D29: 15 | E29: Poste suspensión | I29: 6 | S29: Contaminación. Cadenas de aisladores con el pin de acople a la grapa de suspensión de la línea con corrosión. | Y29: 45390 | Z29: X | AA29: 6
B30: U.P. PESADO | C30: MEREY-20 | D30: 16 | E30: Poste suspensión | I30: 6 | S30: Contaminación | Y30: 45390 | Z30: X | AA30: 6
B31: U.P. PESADO | C31: MEREY-20 | D31: 17 | E31: Amarre | I31: 12 | N31: 6 | O31: 12 | S31: Contaminación | T31: 45364 | U31: X | V31: 12 | Y31: 45390 | Z31: X | AA31: 18
B32: U.P. PESADO | C32: MEREY-20 | D32: 18 | E32: Amarre | I32: 12 | O32: 12 | S32: Contaminación | T32: 45364 | U32: X | V32: 12 | Y32: 45390 | Z32: X | AA32: 12
B33: U.P. PESADO | C33: MEREY-20 | D33: 19 | E33: Poste suspensión | I33: 6 | S33: Contaminación | Y33: 45390 | Z33: X | AA33: 6 | AB33: NIVEL 3: AC EFECTO CORONA EN FASE A, B Y C
B34: U.P. PESADO | C34: MEREY-20 | D34: 20 | E34: Poste suspensión | I34: 6 | N34: 6 | S34: Contaminación | Y34: 45390 | Z34: X | AA34: 12
B35: U.P. PESADO | C35: MEREY-20 | D35: 21 | E35: Poste suspensión | H35: 1 | I35: 5 | S35: Contaminación | Y35: 45390 | Z35: X | AA35: 6
B36: U.P. PESADO | C36: MEREY-20 | D36: 22 | E36: Poste suspensión | I36: 6 | S36: Contaminación | Y36: 45390 | Z36: X | AA36: 6
B37: U.P. PESADO | C37: MEREY-20 | D37: 23 | E37: Poste suspensión | I37: 6 | N37: 6 | S37: Contaminación | Y37: 45390 | Z37: X | AA37: 12
B38: U.P. PESADO | C38: MEREY-20 | D38: 24 | E38: Poste suspensión | I38: 6 | S38: Contaminación. Cadenas de aisladores con el pin de acople a la grapa de suspensión de la línea con corrosión. | Y38: 45390 | Z38: X | AA38: 6
B39: U.P. PESADO | C39: MEREY-20 | D39: 25 | E39: Amarre | I39: 12 | O39: 21 | P39: 3 | R39: X | S39: Contaminación | T39: 45364 | U39: X | V39: 30 | Y39: 45390 | Z39: X | AA39: 18
B40: U.P. PESADO | C40: MEREY-20 | D40: 26 | E40: Amarre | I40: 12 | N40: 6 | O40: 12 | S40: Contaminación | T40: 45364 | U40: X | V40: 12 | Y40: 45390 | Z40: X | AA40: 18
B41: U.P. PESADO | C41: MEREY-20 | D41: 27 | E41: Poste suspensión | I41: 6 | S41: Contaminación | Y41: 45390 | Z41: X | AA41: 6
B42: U.P. PESADO | C42: MEREY-20 | D42: 28 | E42: Poste suspensión | I42: 6 | S42: Contaminación | Y42: 45390 | Z42: X | AA42: 6
B43: U.P. PESADO | C43: MEREY-20 | D43: 29 | E43: Poste suspensión | I43: 6 | N43: 6 | S43: Contaminación | Y43: 45390 | Z43: X | AA43: 12
B44: U.P. PESADO | C44: MEREY-20 | D44: 30 | E44: Poste suspensión | I44: 6 | S44: Contaminación | Y44: 45390 | Z44: X | AA44: 6
B45: U.P. PESADO | C45: MEREY-20 | D45: 31 | E45: Poste suspensión | I45: 6 | S45: Contaminación | Y45: 45390 | Z45: X | AA45: 6
...

Sheet Remiga
E3: Calidad | AF3: CODIGO: FO-CA-GE-02-E
AF4: REVISION: 00
E5: Máster de Inspección | AF5: FECHA DE EMISIÓN: 28-02-2024
B8: Nombre del Proyecto: | E8: "Mantenimiento En El Sistema Eléctrico De Distribución 13.8 Kv De La División Ayacucho" | Y8: Nro. de Contrato: | AB8: 4600135303
B9: Disciplina | E9: Electricidad | Y9: Ubicación: | AB9: División Ayacucho
B10: DATOS | F10: MANTENIMIENTO PREDICTIVO EJECUTADO | AD10: MANTENIMIENTO PREVENTIVO EJECUTADO
F12: VISUAL | T12: TERMOGRAFÍA | Y12: ULTRASONIDO | AD12: INTERVENCIÓN
F13: Componentes
B14: Frente | C14: Circuito | D14: Nro. De poste | E14: Descripción | F14: Fecha V | G14: Aislador de Espiga (AE) | H14: Aislador Polimericos (APT ) 34,5 Kv | I14: Aislador de Cadena (Ac) | J14: Aislador Polimericos (APs ) 69 Kv | K14: Cortacorriente (CC) | L14: Abierto | M14: Cerrado | N14: Pararrayos (P) | O14: Grapa ( G ) | P14: Seccionador (SM) | Q14: Abierto 2 | R14: Cerrado3 | S14: Falla Detectada V | T14: Fecha T | U14: Ejecutado T | V14: Puntos de Termografía | W14: Falla Detectada T | X14: Observación T | Y14: Fecha UT | Z14: Ejecutado UT | AA14: Puntos de Ultrasonido | AB14: Falla Detectada UT | AC14: Observación UT | AD14: Fecha | AE14: Ejecutado MTTO | AF14: Observación
B15: U.P. PESADO | C15: REMIGA | D15: 0 | E15: Estructura | G15: 3 | J15: 3 | N15: 3 | O15: 6 | P15: 3 | T15: 45205 | U15: X | V15: 12
B16: U.P. PESADO | C16: REMIGA | D16: 1 | E16: Amarre 90° | G16: 3 | H16: 6 | J16: 3 | O16: 12 | P16: 6 | T16: 45205 | U16: X | V16: 14
B17: U.P. PESADO | C17: REMIGA | D17: 2 | E17: Estructura de Amarre | H17: 12 | O17: 12 | T17: 45205 | U17: X | V17: 12
B18: U.P. PESADO | C18: REMIGA | D18: 3 | E18: Estructura de Amarre | H18: 12 | O18: 12 | T18: 45205 | U18: X | V18: 12
B19: U.P. PESADO | C19: REMIGA | D19: 4 | E19: Suspensión | H19: 6 | T19: 45205 | U19: X | V19: 6
B20: U.P. PESADO | C20: REMIGA | D20: 5 | E20: Suspensión | H20: 6 | T20: 45205 | U20: X | V20: 6
B21: U.P. PESADO | C21: REMIGA | D21: 6 | E21: Amarre | G21: 2 | H21: 6 | J21: 6 | O21: 12 | T21: 45205 | U21: X | V21: 14
B22: U.P. PESADO | C22: REMIGA | D22: 7 | E22: Amarre | G22: 2 | J22: 12 | O22: 12 | T22: 45205 | U22: X | V22: 14
B23: U.P. PESADO | C23: REMIGA | D23: 8 | E23: Suspensión | H23: 6 | T23: 45205 | U23: X | V23: 6
B24: U.P. PESADO | C24: REMIGA | D24: 9 | E24: Suspensión | H24: 6 | T24: 45205 | U24: X | V24: 6
B25: U.P. PESADO | C25: REMIGA | D25: 10 | E25: Suspensión | H25: 6 | T25: 45205 | U25: X | V25: 6
B26: U.P. PESADO | C26: REMIGA | D26: 11 | E26: Suspensión | H26: 6 | T26: 45205 | U26: X | V26: 6
B27: U.P. PESADO | C27: REMIGA | D27: 12 | E27: Amarre | G27: 2 | J27: 12 | O27: 12 | T27: 45205 | U27: X | V27: 14
B28: U.P. PESADO | C28: REMIGA | D28: 13 | E28: Suspensión | H28: 6 | T28: 45205 | U28: X | V28: 6
B29: U.P. PESADO | C29: REMIGA | D29: 14 | E29: Suspensión | H29: 6 | T29: 45205 | U29: X | V29: 6
B30: U.P. PESADO | C30: REMIGA | D30: 15 | E30: Suspensión | H30: 6 | T30: 45205 | U30: X | V30: 6
B31: U.P. PESADO | C31: REMIGA | D31: 16 | E31: Suspensión | H31: 6 | T31: 45205 | U31: X | V31: 6
B32: U.P. PESADO | C32: REMIGA | D32: 17 | E32: Amarre | G32: 2 | J32: 12 | O32: 12 | T32: 45205 | U32: X | V32: 14
B33: U.P. PESADO | C33: REMIGA | D33: 18 | E33: Suspensión | H33: 6 | T33: 45205 | U33: X | V33: 6
B34: U.P. PESADO | C34: REMIGA | D34: 19 | E34: Amarre 30° | G34: 2 | J34: 12 | O34: 12 | T34: 45205 | U34: X | V34: 14
B35: U.P. PESADO | C35: REMIGA | D35: 20 | E35: Suspensión | H35: 6 | T35: 45205 | U35: X | V35: 6
B36: U.P. PESADO | C36: REMIGA | D36: 21 | E36: Suspensión | H36: 6 | T36: 45205 | U36: X | V36: 6
B37: U.P. PESADO | C37: REMIGA | D37: 22 | E37: Amarre | G37: 2 | J37: 12 | O37: 12 | T37: 45205 | U37: X | V37: 14
B38: U.P. PESADO | C38: REMIGA | D38: 23 | E38: Suspensión | H38: 6 | T38: 45205 | U38: X | V38: 6
B39: U.P. PESADO | C39: REMIGA | D39: 24 | E39: Suspensión | H39: 6 | T39: 45205 | U39: X | V39: 6
B40: U.P. PESADO | C40: REMIGA | D40: 25 | E40: Suspensión | H40: 6 | T40: 45205 | U40: X | V40: 6
B41: U.P. PESADO | C41: REMIGA | D41: 26 | E41: Suspensión | H41: 6 | T41: 45205 | U41: X | V41: 6
B42: U.P. PESADO | C42: REMIGA | D42: 27 | E42: Amarre | G42: 2 | J42: 12 | O42: 12 | T42: 45205 | U42: X | V42: 14
B43: U.P. PESADO | C43: REMIGA | D43: 28 | E43: Suspensión | H43: 4 | J43: 2 | T43: 45205 | U43: X | V43: 6
B44: U.P. PESADO | C44: REMIGA | D44: 29 | E44: Suspensión | H44: 4 | J44: 2 | T44: 45205 | U44: X | V44: 6
B45: U.P. PESADO | C45: REMIGA | D45: 30 | E45: Suspensión | H45: 4 | J45: 2 | T45: 45205 | U45: X | V45: 6
...

Sheet Este
E3: Calidad | AF3: CODIGO: FO-CA-GE-02-E
AF4: REVISION: 00
E5: Máster de Inspección | AF5: FECHA DE EMISIÓN: 28-02-2024
B8: Nombre del Proyecto: | E8: "Mantenimiento En El Sistema Eléctrico De Distribución 13.8 Kv De La División Ayacucho" | Y8: Nro. de Contrato: | AB8: 4600135303
B9: Disciplina | E9: Electricidad | Y9: Ubicación: | AB9: División Ayacucho
B10: DATOS | F10: MANTENIMIENTO PREDICTIVO EJECUTADO | AD10: MANTENIMIENTO PREVENTIVO EJECUTADO
F12: VISUAL | T12: TERMOGRAFÍA | Y12: ULTRASONIDO | AD12: INTERVENCIÓN
F13: Componentes
B14: Frente | C14: Circuito | D14: Nro. De poste | E14: Descripción | F14: Fecha V | G14: Aislador de Espiga (AE) | H14: Aislador Polimericos (APT ) 34,5 Kv | I14: Aislador de Cadena (Ac) | J14: Aislador Polimericos (APs ) 69 Kv | K14: Cortacorriente (CC) | L14: Abierto | M14: Cerrado | N14: Pararrayos (P) | O14: Grapa ( G ) | P14: Seccionador (SM) | Q14: Abierto 2 | R14: Cerrado3 | S14: Falla Detectada V | T14: Fecha T | U14: Ejecutado T | V14: Puntos de Termografía | W14: Falla Detectada T | X14: Observación T | Y14: Fecha UT | Z14: Ejecutado UT | AA14: Puntos de Ultrasonido | AB14: Falla Detectada UT | AC14: Observación UT | AD14: Fecha | AE14: Ejecutado MTTO | AF14: Observación
B15: U.P. PESADO | C15: ESTE | D15: 1 | E15: Amarre | H15: 6 | N15: 3 | P15: 3 | S15: Contaminación. Bajante de PAT de los pararrayos cortado. Seccionadores M-450 cerrados.
B16: U.P. PESADO | C16: ESTE | D16: 2 | E16: Pase con Derivación en 90° | G16: 6 | H16: 3 | I16: 2 | K16: 2 | S16: NIVEL 3: Curceta doblada. Asialdores de espigas inclinados. Se debe corregir esta irregularidad.
B17: U.P. PESADO | C17: ESTE | D17: 3 | E17: Pase | G17: 3 | N17: 3 | S17: Contaminación
B18: U.P. PESADO | C18: ESTE | D18: 4 | E18: Pase | G18: 2 | I18: 2 | S18: Contaminación. En el vano comprendido entre los postes 4 y 5 hay un pino cercano a la línea. Se recomienda poda.
B19: U.P. PESADO | C19: ESTE | D19: 5 | E19: Amarre con Derivación en 90° | I19: 9 | S19: Contaminación. En el vano comprendido entre los postes 4 y 5 hay un pino cercano a la línea. Se recomienda poda.
B20: U.P. PESADO | C20: ESTE | D20: 6 | E20: Pase | G20: 3 | N20: 3 | S20: Contaminación
B21: U.P. PESADO | C21: ESTE | D21: 7 | E21: Pase | G21: 3 | S21: Contaminación
B22: U.P. PESADO | C22: ESTE | D22: 8 | E22: Pase | G22: 3 | N22: 3 | S22: Contaminación
B23: U.P. PESADO | C23: ESTE | D23: 9 | E23: Pase | G23: 3 | S23: Contaminación
B24: U.P. PESADO | C24: ESTE | D24: 10 | E24: Pase | G24: 3 | N24: 3 | S24: Contaminación. Poste sin PAT.
B25: U.P. PESADO | C25: ESTE | D25: 11 | E25: Pase | G25: 3 | I25: 2 | S25: Contaminación
B26: U.P. PESADO | C26: ESTE | D26: 12 | E26: Amarre con Derivación en 90° | I26: 9 | S26: Contaminación
B27: U.P. PESADO | C27: ESTE | D27: 13 | E27: Pase | G27: 3 | N27: 3 | S27: Contaminación
B28: U.P. PESADO | C28: ESTE | D28: 14 | E28: Pase | G28: 3 | S28: Contaminación. Palillos con cierto grado de corrosión en el acople al aislador. Aislador de la fase C presenta inclinación. Se debe corregir esta irregularidad.
B29: U.P. PESADO | C29: ESTE | D29: 15 | E29: Pase | G29: 3 | N29: 3 | S29: Contaminación. Palillos con cierto grado de corrosión en el acople al aislador.
B30: U.P. PESADO | C30: ESTE | D30: 16 | E30: Pase | G30: 3 | S30: Contaminación. Palillos con cierto grado de corrosión en el acople al aislador.
B31: U.P. PESADO | C31: ESTE | D31: 17 | E31: Pase | G31: 3 | N31: 3 | S31: Contaminación. Palillos con cierto grado de corrosión en el acople al aislador.
B32: U.P. PESADO | C32: ESTE | D32: 18 | E32: Pase | G32: 3 | S32: Contaminación
B33: U.P. PESADO | C33: ESTE | D33: 19 | E33: Amarre en 45° con Derivación en 90° | I33: 12 | S33: Contaminación
B34: U.P. PESADO | C34: ESTE | D34: 20 | E34: Amarre en 45° | I34: 6 | S34: Contaminación. Poste sin PAT.
B35: U.P. PESADO | C35: ESTE | D35: 21 | E35: Amarre | H35: 1 | I35: 5 | P35: 3 | S35: Contaminación. Seccionadores cerrados. Nido de aves en el seccionador de la fase C.
B36: U.P. PESADO | C36: ESTE | D36: 22 | E36: Pase | G36: 3 | N36: 3 | S36: Contaminación
B37: U.P. PESADO | C37: ESTE | D37: 23 | E37: Amarre con Derivación en 45° | I37: 9 | S37: Contaminación
B38: U.P. PESADO | C38: ESTE | D38: 24 | E38: Pase | G38: 3 | K38: 3 | N38: 3 | S38: Contaminación. Tres cortacorrientes abiertos. Se recomienda retirarlos.
B39: U.P. PESADO | C39: ESTE | D39: 25 | E39: Pase | G39: 3 | K39: 3 | S39: Contaminación. Tres cortacorrientes abiertos y sin conexión a la línea. Se recomienda retirarlos.
B40: U.P. PESADO | C40: ESTE | D40: 26 | E40: Amarre en 45° | I40: 6 | S40: Contaminación. Poste sin PAT.
B41: U.P. PESADO | C41: ESTE | D41: 27 | E41: Amarre con Derivación en 45° | I41: 9 | S41: Contaminación
B42: U.P. PESADO | C42: ESTE | D42: 28 | E42: Amarre | I42: 6 | N42: 3 | P42: 3 | S42: Contaminación. Seccionadores cerrados.
B43: U.P. PESADO | C43: ESTE | D43: 29 | E43: Pase | G43: 3 | S43: Contaminación. Poste sin PAT.
B44: U.P. PESADO | C44: ESTE | D44: 30 | E44: Pase con Derivación en 45° | G44: 3 | I44: 3 | N44: 3 | P44: 3 | S44: NIVEL 3: Palillos con alto grado de corrosión. Se recomienda cambiarlos. Seccionadores cerrados.
B45: U.P. PESADO | C45: ESTE | D45: 31 | E45: Pase | G45: 3 | S45: Contaminación. Palillos con cierto grado de corrosión. Poste sin PAT.
...

Sheet Oeste
E3: Calidad | AF3: CODIGO: FO-CA-GE-02-E
AF4: REVISION: 00
E5: Máster de Inspección | AF5: FECHA DE EMISIÓN: 28-02-2024
B8: Nombre del Proyecto: | E8: "Mantenimiento En El Sistema Eléctrico De Distribución 13.8 Kv De La División Ayacucho" | Y8: Nro. de Contrato: | AB8: 4600135303
B9: Disciplina | E9: Electricidad | Y9: Ubicación: | AB9: División Ayacucho
B10: DATOS | F10: MANTENIMIENTO PREDICTIVO EJECUTADO | AD10: MANTENIMIENTO PREVENTIVO EJECUTADO
F12: VISUAL | T12: TERMOGRAFÍA | Y12: ULTRASONIDO | AD12: INTERVENCIÓN
F13: Componentes
B14: Frente | C14: Circuito | D14: Nro. De poste | E14: Descripción | F14: Fecha V | G14: Aislador de Espiga (AE) | H14: Aislador Polimericos (APT ) 34,5 Kv | I14: Aislador de Cadena (Ac) | J14: Aislador Polimericos (APs ) 69 Kv | K14: Cortacorriente (CC) | L14: Abierto | M14: Cerrado | N14: Pararrayos (P) | O14: Grapa ( G ) | P14: Seccionador (SM) | Q14: Abierto 2 | R14: Cerrado3 | S14: Falla Detectada V | T14: Fecha T | U14: Ejecutado T | V14: Puntos de Termografía | W14: Falla Detectada T | X14: Observación T | Y14: Fecha UT | Z14: Ejecutado UT | AA14: Puntos de Ultrasonido | AB14: Falla Detectada UT | AC14: Observación UT | AD14: Fecha | AE14: Ejecutado MTTO | AF14: Observación
B15: U.P. PESADO | C15: OESTE | D15: 1 | E15: Amarre | G15: 3 | H15: 6 | N15: 3 | P15: 3 | S15: Contaminación. Tres seccionadores abiertos. Herajes (pernos rocados) con cierto grado de corrosión. Poste sin PAT. Cable de guarda cortado entre los postes 1 y 2. corregir esta irregularidad.
B16: U.P. PESADO | C16: OESTE | D16: 2 | E16: Pase con Derivación en 90° | G16: 6 | H16: 3 | N16: 3 | P16: 3 | S16: Aisladores y pararrayos muy contaminados. Un pararrayos desconectado de la línea. Dos aisladores de espigas de 15 kV sin conexión a la línea. Tres seccionadores cerrados que van hacia una derivación que interconecta con el Circuito Este.
B17: U.P. PESADO | C17: OESTE | D17: 3 | E17: Pase | G17: 3 | K17: 2 | N17: 3 | S17: Contaminación. Uno de los pararrayos esta desconectado de la línea, y cuelga del cable de PAT. Corrigir esta irregularidad. Dos cortacorrientes fuera de servicio (desconectados de la línea).
B18: U.P. PESADO | C18: OESTE | D18: 4 | E18: Pase | G18: 3 | K18: 1 | S18: Contaminación. Un cortacorriente fuera de servicio. (Sin conexión a la línea)
B19: U.P. PESADO | C19: OESTE | D19: 5 | E19: Amarre con Derivación en 90° | H19: 9 | S19: Contaminación
B20: U.P. PESADO | C20: OESTE | D20: 6 | E20: Amarre | H20: 6 | P20: 3 | S20: Contaminación. Seccionadores M-162 cerrados.
B21: U.P. PESADO | C21: OESTE | D21: 7 | E21: Pase | G21: 3 | N21: 3 | S21: Contaminación
B22: U.P. PESADO | C22: OESTE | D22: 8 | E22: Pase | G22: 3 | S22: Contaminación
B23: U.P. PESADO | C23: OESTE | D23: 9 | E23: Pase Tx | G23: 3 | K23: 3 | N23: 3 | S23: Contaminación. Tres cortacorrientes cerrados y con transformador conectado. Poste sin PAT. Red de baja tensión en la misma posteadura.
B24: U.P. PESADO | C24: OESTE | D24: 10 | E24: Pase | G24: 3 | S24: Contaminación. Poste sin PAT.
B25: U.P. PESADO | C25: OESTE | D25: 11 | E25: Pase | G25: 3 | N25: 3 | S25: Contaminación. No se aprecia la PAT del poste.
B26: U.P. PESADO | C26: OESTE | D26: 12 | E26: Amarre con Derivación en 90° | H26: 9 | S26: Contaminación
B27: U.P. PESADO | C27: OESTE | D27: 13 | E27: Pase | G27: 3 | S27: Contaminación
B28: U.P. PESADO | C28: OESTE | D28: 14 | E28: Amarre con Derivación en 90° | H28: 9 | S28: Contaminación. Poste sin PAT.
B29: U.P. PESADO | C29: OESTE | D29: 15 | E29: Poste Terminal | G29: 8 | H29: 9 | K29: 3 | N29: 3 | S29: Contaminación. Tres cortacorrientes abiertos y sin carga conectada. No se aprecia la PAT del poste.
B30: U.P. PESADO | C30: OESTE | D30: 16 | E30: Amarre | G30: 1 | H30: 3 | I30: 3 | S30: Contaminación. Poste sin PAT.
B31: U.P. PESADO | C31: OESTE | D31: 17 | E31: Pase con Derivación en 90° | G31: 4 | H31: 3 | K31: 3 | N31: 3 | S31: Contaminación. Derivación a traves de tres cortacorrientes que estan cerrados. Poste sin PAT.
B32: U.P. PESADO | C32: OESTE | D32: 18 | E32: Pase | G32: 3 | S32: Contaminación. Poste sin PAT.
B33: U.P. PESADO | C33: OESTE | D33: 19 | E33: Poste Terminal | I33: 3 | N33: 3 | S33: Contaminación. Poste sin PAT.
B34: U.P. PESADO | C34: OESTE | D34: 20 | E34: Amarre | G34: 1 | H34: 6 | S34: Contaminación. Poste sin PAT.
B35: U.P. PESADO | C35: OESTE | D35: 21 | E35: Pase | G35: 3 | S35: Contaminación. Poste sin PAT.
B36: U.P. PESADO | C36: OESTE | D36: 22 | E36: Pase | G36: 3 | N36: 3 | S36: Contaminación. Poste sin PAT.
B37: U.P. PESADO | C37: OESTE | D37: 23 | E37: Amarre en 90° | G37: 2 | H37: 6 | S37: Contaminación. Poste sin PAT.
B38: U.P. PESADO | C38: OESTE | D38: 24 | E38: Poste Terminal Tx | H38: 3 | K38: 3 | N38: 3 | S38: Aisladores y pararrayos muy contaminados. Tres cortacorrientes cerrados que dan hacia un banco de tansformadores. Poste sin PAT.
B39: U.P. PESADO | C39: OESTE | D39: 25 | E39: Amarre | I39: 6 | N39: 3 | P39: 6 (1 ST) | S39: Contaminación. Seis seccionadores monopolares cerrados y uno tripolar abierto. Árboles de mediana altura rosando la estructura. Se debe podar.
B40: U.P. PESADO | C40: OESTE | D40: 26 | E40: Pase con Derivación en 90° | G40: 3 | I40: 3 | S40: Contaminación
B41: U.P. PESADO | C41: OESTE | D41: 27 | E41: Poste Terminal | I41: 3 | K41: 3 | S41: Contaminación. Tres cortacorrientes abiertos y sin carga conectada. Poste sin PAT.
B42: U.P. PESADO | C42: OESTE | D42: 28 | E42: Pase | G42: 3 | N42: 2 | S42: Contaminación. Un pararrayos desprendido. Se recomienda instalar un nuevo juego de pararrayos.
B43: U.P. PESADO | C43: OESTE | D43: 29 | E43: Pase | G43: 3 | S43: NIVEL 3: Contaminación. Aislador de la fase A fogoneado. Se debe reemplazar. Poste sin PAT.
B44: U.P. PESADO | C44: OESTE | D44: 30 | E44: Pase con Derivación en 90° | G44: 3 | H44: 2 | K44: 2 | N44: 3 | S44: Contaminación. Aislador de la fase B desacoplado del palillo. Corregir esta irregularidad. Derivación monofásica hacia finca a traves de dos cortacorrientes que estan cerrados.
B45: U.P. PESADO | C45: OESTE | D45: 31 | E45: Pase | G45: 3 | N45: 3 | S45: Contaminación. En el vano comprendido entre los postes 31 y 32 se recomienda colocar separadores de línea con aisladores polimericos.
...

Sheet Norte
E3: Calidad | AF3: CODIGO: FO-CA-GE-02-E
AF4: REVISION: 00
E5: Máster de Inspección | AF5: FECHA DE EMISIÓN: 28-02-2024
B8: Nombre del Proyecto: | E8: "Mantenimiento En El Sistema Eléctrico De Distribución 13.8 Kv De La División Ayacucho" | Y8: Nro. de Contrato: | AB8: 4600135303
B9: Disciplina | E9: Electricidad | Y9: Ubicación: | AB9: División Ayacucho
B10: DATOS | F10: MANTENIMIENTO PREDICTIVO EJECUTADO | AD10: MANTENIMIENTO PREVENTIVO EJECUTADO
F12: VISUAL | T12: TERMOGRAFÍA | Y12: ULTRASONIDO | AD12: INTERVENCIÓN
F13: Componentes
B14: Frente | C14: Circuito | D14: Nro. De poste | E14: Descripción | F14: Fecha V | G14: Aislador de Espiga (AE) | H14: Aislador Polimericos (APT ) 34,5 Kv | I14: Aislador de Cadena (Ac) | J14: Aislador Polimericos (APs ) 69 Kv | K14: Cortacorriente (CC) | L14: Abierto | M14: Cerrado | N14: Pararrayos (P) | O14: Grapa ( G ) | P14: Seccionador (SM) | Q14: Abierto 2 | R14: Cerrado3 | S14: Falla Detectada V | T14: Fecha T | U14: Ejecutado T | V14: Puntos de Termografía | W14: Falla Detectada T | X14: Observación T | Y14: Fecha UT | Z14: Ejecutado UT | AA14: Puntos de Ultrasonido | AB14: Falla Detectada UT | AC14: Observación UT | AD14: Fecha | AE14: Ejecutado MTTO | AF14: Observación
B15: U.P. PESADO | C15: NORTE | D15: 1 | E15: Amarre | I15: 6 | N15: 3 | P15: 3 | S15: Contaminación. Seccionadores M-192 abiertos.
B16: U.P. PESADO | C16: NORTE | D16: 2 | E16: Suspensión | H16: 1 | I16: 2 | N16: 3 | S16: Contaminación
B17: U.P. PESADO | C17: NORTE | D17: 3 | E17: Suspensión con Derivación en 45° | G17: 1 | I17: 6 | P17: 3 | S17: NIVEL 3: Contaminación. Cadena de aisladores de la fase A de la derivación esta fogoneado. Se debe cambiar. Seccionadores M-136 cerrados. Poste de interconexión del Circuito Lejos con el Circuito Norte de la S/E Melones.
B18: U.P. PESADO | C18: NORTE | D18: 4 | E18: Suspensión | I18: 3 | N18: 1 | S18: NIVEL 3: Contaminación. Pararrayos dañados. Pin de acople de los aisladores con corrosión. Se deben cambiar. Se deben instalar tres nuevos pararrayos.
B19: U.P. PESADO | C19: NORTE | D19: 5 | E19: Suspensión | I19: 3 | N19: 1 | S19: NIVEL 3: Contaminación. Pin de acople de los aisladores con corrosión. Se deben cambiar. Pararrayos deteriorados. Se deben instalar tres nuevos pararrayos.
B20: U.P. PESADO | C20: NORTE | D20: 6 | E20: Suspensión | I20: 3 | N20: 3 | S20: Contaminación. Pararrayos deteriorados. Se deben reemplazar. Pin de acople de los aisladores con cierto grado de corrosión. Se recomienda cambiarlos.
B21: U.P. PESADO | C21: NORTE | D21: 7 | E21: Suspensión | I21: 3 | S21: Contaminación. Pin de acople de los aisladores con cierto grado de corrosión. Se recomienda cambiarlos.
B22: U.P. PESADO | C22: NORTE | D22: 8 | E22: Suspensión | I22: 3 | N22: 3 | S22: NIVEL 3: Contaminación. Pin de acople de los aisladores con corrosión. Se deben cambiar. Pinos cercanos a la línea. Se debe podar.
B23: U.P. PESADO | C23: NORTE | D23: 9 | E23: Suspensión | I23: 3 | S23: Contaminación. Poste sin PAT.
B24: U.P. PESADO | C24: NORTE | D24: 10 | E24: Suspensión | I24: 3 | N24: 3 | S24: NIVEL 3: Contaminación. Pin de acople y rótula ojo de los aisladores con alto grado de corrosión y pérdida de material. Se deben cambiar de inmediato.
B25: U.P. PESADO | C25: NORTE | D25: 11 | E25: Amarre | I25: 6 | S25: Contaminación
B26: U.P. PESADO | C26: NORTE | D26: 12 | E26: Amarre | I26: 8 | K26: 2 | S26: Contaminación. Dos cortacorrientes abiertos y sin carga conectada. Dos cadenas de aisladores que daban hacia una derivación que se encuentra desmantelada.
B27: U.P. PESADO | C27: NORTE | D27: 13 | E27: Suspensión | I27: 3 | S27: NIVEL 3: Contaminación. Pin de acople de los aisladores con corrosión. Se deben cambiar.
B28: U.P. PESADO | C28: NORTE | D28: 14 | E28: Suspensión | I28: 3 | N28: 2 | S28: NIVEL 3: Contaminación. Falta un pararrayos. Los dos que están instalados presentan deterioro. Pin de acople de los aisladores de las fases A y B con alto grado de corrosión y pérdida de material. Se deben cambiar las tres cadenas de aisladores. Se recomienda instalar nuevo juego de pararrayos.
B29: U.P. PESADO | C29: NORTE | D29: 15 | E29: Suspensión | I29: 3 | S29: Contaminación. Pin de acople de los aisladores con cierto grado de corrosión. Se recomienda cambiarlos. Poste sin PAT.
B30: U.P. PESADO | C30: NORTE | D30: 16 | E30: Suspensión | I30: 3 | N30: 3 | S30: Contaminación
B31: U.P. PESADO | C31: NORTE | D31: 17 | E31: Suspensión | I31: 3 | S31: NIVEL 3: Contaminación. Pin de acople de los aisladores con corrosión. Se deben cambiar. Poste sin PAT.
B32: U.P. PESADO | C32: NORTE | D32: 18 | E32: Suspensión | I32: 3 | S32: Contaminación. Pin de acople de los aisladores con cierto grado de corrosión. Se recomienda cambiarlos. Poste sin PAT.
B33: U.P. PESADO | C33: NORTE | D33: 19 | E33: Suspensión | I33: 3 | N33: 3 | S33: Contaminación. Pin de acople de los aisladores con cierto grado de corrosión. Se recomienda cambiarlos.
